Workbook
Name OLE_LINK1: 'Datos ICP (2)'!#REF!

Sheet Comentario
A2: El IPC de abril registró una variación mensual de 1,2%, llevando la inflación anual a 4,0%, por encima de las expectativas del mercado. El alza estuvo impulsada principalmente por los combustibles y su traspaso al componente de transporte. El componente volátil de energía acumuló un avance mensual de 12,9%, reflejando especialmente los incrementos en los precios de la gasolina y el diésel asociados al shock energético observado a fines de marzo. La inflación subyacente continuó mostrando una dinámica relativamente contenida, con un aumento de 0,5% mensual y 3,5% anual. Tanto los servicios como los bienes subyacentes mantuvieron variaciones acotadas, sin señales relevantes de efectos de segunda vuelta asociados a una aceleración de la demanda. Si bien el traspaso del shock en combustibles sigue siendo limitado fuera de los componentes más volátiles, su impacto continuará siendo monitoreado en los próximos meses. Por su parte, el Banco Central mantuvo la tasa de política monetaria en 4,5%, manteniendo una postura cautelosa ante la incertidumbre asociada a la evolución del conflicto en Medio Oriente, la trayectoria del precio del petróleo y sus potenciales efectos sobre la convergencia inflacionaria.

Sheet Datos ICP (2)
A1: CLICP Index | F1: Cuota Liquidez Temporal | AD1: ICP | AE1: Ene | AF1: Feb | AG1: Mar | AH1: Abr | AI1: May | AJ1: Jun | AK1: Jul | AL1: Ago | AM1: Sep | AN1: Oct | AO1: Nov | AP1: Dic | AQ1: Total Año
A2: Fecha | B2: ICP | D2: ICP Norm. | J2: Fondo Liquidez Temporal | K2: 8730-0 | M2: Competencia Relevante (*) | P2: Ene | Q2: Feb | R2: Mar | S2: Abr | T2: May | U2: Jun | V2: Jul | W2: Ago | X2: Sep | Y2: Oct | Z2: Nov | AA2: Dic | AD2: 2006
A3: 38717 | B3: 10953.14 | K3: SERIE E | N3: =B3 | O3: 2006 | AD3: 2007
A4: 38748 | B4: 10996.85 | C4: =(B4/B3-1)/(A4-A3)*30 | K4: BCI EFICIENTE | O4: 2007 | AD4: 2008
A5: 38776 | B5: 11035.11 | C5: =(B5/B4-1)/(A5-A4)*30 | O5: 2008 | AD5: 2009
A6: 38807 | B6: 11078.66 | C6: =(B6/B5-1)/(A6-A5)*30 | O6: 2009 | AD6: 2010
A7: 38835 | B7: 11118.82 | C7: =(B7/B6-1)/(A7-A6)*30 | O7: 2010 | AD7: 2011
A8: 38868 | B8: 11169.1 | C8: =(B8/B7-1)/(A8-A7)*30 | O8: 2011 | AD8: 2012
A9: 38898 | B9: 11215.04 | C9: =(B9/B8-1)/(A9-A8)*30 | O9: 2012 | AD9: 2013
A10: 38929 | B10: 11263.22 | C10: =(B10/B9-1)/(A10-A9)*30 | O10: 2013 | AD10: 2014
A11: 38960 | B11: 11313.29 | C11: =(B11/B10-1)/(A11-A10)*30 | O11: 2014 | AD11: 2015
A12: 38989 | B12: 11360.92 | C12: =(B12/B11-1)/(A12-A11)*30 | O12: 2015 | AD12: 2016
A13: 39021 | B13: 11413.02 | C13: =(B13/B12-1)/(A13-A12)*30 | O13: 2016 | AD13: 2017
A14: 39051 | B14: 11463.01 | C14: =(B14/B13-1)/(A14-A13)*30 | O14: 2017 | AD14: 2018
A15: 39080 | B15: 11512.49 | C15: =(B15/B14-1)/(A15-A14)*30 | O15: 2018 | AD15: 2019 | AR15: (*)
A16: 39113 | B16: 11567.23 | C16: =(B16/B15-1)/(A16-A15)*30 | O16: 2019 | AD16: 2020
A17: 39141 | B17: 11612.68 | C17: =(B17/B16-1)/(A17-A16)*30 | O17: 2020 | AD17: 2021
A18: 39171 | B18: 11661.5 | C18: =(B18/B17-1)/(A18-A17)*30 | O18: 2021 | AD18: 2022 | AX18: -1 | AY18: -3 | AZ18: -6 | BA18: -12
A19: 39202 | B19: 11712.58 | C19: =(B19/B18-1)/(A19-A18)*30 | O19: 2022 | AD19: 2023 | AV19: Ingresar mes actual==> | AW19: 46142 | AX19: =EOMONTH($AW19,AX18)+6+1 | AY19: =EOMONTH($AW19,AY18) | AZ19: =EOMONTH($AW19,AZ18) | BA19: =EOMONTH($AW19,BA18) | BB19: 43100
A20: 39233 | B20: 11763.78 | C20: =(B20/B19-1)/(A20-A19)*30 | O20: 2023 | AD20: 2024 | AV20: ICP | AW20: =LOOKUP(AW19,$A$3:$A$2973,$B$3:$B$2973) | AX20: =LOOKUP(AX19,$A$3:$A$2973,$B$3:$B$2973) | AY20: =LOOKUP(AY19,$A$3:$A$2973,$B$3:$B$2973) | AZ20: =LOOKUP(AZ19,$A$3:$A$2973,$B$3:$B$2973) | BA20: =LOOKUP(BA19,$A$3:$A$2973,$B$3:$B$2973) | BB20: =LOOKUP(BB19,$A$3:$A$2973,$B$3:$B$2973)
A21: 39262 | B21: 11812.23 | C21: =(B21/B20-1)/(A21-A20)*30 | O21: 2024 | AD21: 2025 | AE21: 0 | AF21: =+Q22/P22-1 | AG21: =+R22/Q22-1 | AH21: =+S22/R22-1 | AI21: =+T22/S22-1 | AJ21: =+U22/T22-1 | AK21: =+V22/U22-1 | AL21: =+W22/V22-1 | AM21: =+X22/W22-1 | ... AP21: =+AA22/Z22-1 | AQ21: =+(AA22/P22-1)/COUNTA(AE21:AP21)*12 | AV21: Competencia | AW21: =LOOKUP(AW19,$F$2:$F$2974,$K$2:$K$2974) | AX21: =LOOKUP(AX19,$F$2:$F$2974,$K$2:$K$2974) | AY21: =LOOKUP(AY19,$F$2:$F$2974,$K$2:$K$2974) | AZ21: =LOOKUP(AZ19,$F$2:$F$2974,$K$2:$K$2974) | BA21: =LOOKUP(BA19,$F$2:$F$2974,$K$2:$K$2974) | BB21: =LOOKUP(BB19,$F$2:$F$2974,$K$2:$K$2974)
A22: 39294 | B22: 11866.53 | C22: =(B22/B21-1)/(A22-A21)*30 | O22: 2025 | P22: =+B234 | Q22: =+B235 | R22: =+B236 | S22: =+B237 | T22: =+B238 | U22: =+B239 | V22: =+B240 | W22: =+B241 | X22: =+B242 | Y22: =+B243 | Z22: =+B244 | AA22: =+B245 | AD22: 2026 | AE22: =+P23/AA22-1 | AF22: =+Q23/P23-1 | AG22: =+R23/Q23-1 | AH22: =+S23/R23-1 | AQ22: =+(S23/P23-1)/COUNTA(AE22:AP22)*12 | AV22: FIP Liquidez lexible | AW22: =LOOKUP(AW19,$F$2:$F$2972,$H$2:$H$2972) | AX22: =LOOKUP(AX19,$F$2:$F$2972,$H$2:$H$2972) | AY22: =LOOKUP(AY19,$F$2:$F$2972,$H$2:$H$2972) | AZ22: =LOOKUP(AZ19,$F$2:$F$2972,$H$2:$H$2972) | BA22: =LOOKUP(BA19,$F$2:$F$2972,$H$2:$H$2972) | BB22: =LOOKUP(BB19,$F$2:$F$2972,$H$2:$H$2972)
O23: 2026 | P23: =+B246 | Q23: =+B247 | R23: =+B248 | S23: =+B249 | AD23: (*) Acum a Mar
A24: 39325 | B24: 11922.48 | C24: =(B24/B22-1)/(A24-A22)*30 | P24: 31 | Q24: 28 | R24: 31 | S24: 30 | T24: 31 | U24: 30 | V24: 31 | W24: 31 | X24: 30 | Y24: 31 | Z24: 30 | AA24: 31
A25: 39353 | B25: 11975.61 | C25: =(B25/B24-1)/(A25-A24)*30 | P25: 1 | Q25: 2 | R25: 3 | S25: 4 | T25: 5 | U25: 6 | V25: 7 | W25: 8 | X25: 9 | Y25: 10 | Z25: 11 | AA25: 12
A26: 39386 | B26: 12038.9 | C26: =(B26/B25-1)/(A26-A25)*30 | O26: FONDO LIQUIDEZ FLEXIBLE | P26: Ene | Q26: Feb | R26: Mar | S26: Abr | T26: May | U26: Jun | V26: Jul | W26: Ago | X26: Sep | Y26: Oct | Z26: Nov | AA26: Dic
A27: 39416 | B27: 12096.85 | C27: =(B27/B26-1)/(A27-A26)*30 | O27: 2016 | T27: ='[1]Cuota Liquidez '!B2 | U27: =LOOKUP(DATE($O27,U$25,U$24),$A$2:$A$2943,$H$2:$H$2943) | V27: =LOOKUP(DATE($O27,V$25,V$24),$A$2:$A$2943,$H$2:$H$2943) | W27: =LOOKUP(DATE($O27,W$25,W$24),$A$2:$A$2943,$H$2:$H$2943) | X27: =LOOKUP(DATE($O27,X$25,X$24),$A$2:$A$2943,$H$2:$H$2943) | Y27: =LOOKUP(DATE($O27,Y$25,Y$24),$A$2:$A$2943,$H$2:$H$2943) | Z27: =LOOKUP(DATE($O27,Z$25,Z$24),$A$2:$A$2943,$H$2:$H$2943) | AA27: =LOOKUP(DATE($O27,AA$25,AA$24),$A$2:$A$2943,$H$2:$H$2943) | AD27: FLEXIBLE | AE27: Ene | AF27: Feb | AG27: Mar | AH27: Abr | AI27: May | AJ27: Jun | AK27: Jul | AL27: Ago | AM27: Sep | AN27: Oct | AO27: Nov | AP27: Dic | AQ27: Total Año
A28: 39447 | B28: 12152.6 | C28: =(B28/B27-1)/(A28-A27)*30 | O28: 2017 | P28: =LOOKUP(DATE($O28,P$25,P$24),$A$2:$A$2943,$H$2:$H$2943) | Q28: =LOOKUP(DATE($O28,Q$25,Q$24),$A$2:$A$2943,$H$2:$H$2943) | R28: =LOOKUP(DATE($O28,R$25,R$24),$A$2:$A$2943,$H$2:$H$2943) | S28: =LOOKUP(DATE($O28,S$25,S$24),$A$2:$A$2943,$H$2:$H$2943) | T28: =LOOKUP(DATE($O28,T$25,T$24),$A$2:$A$2943,$H$2:$H$2943) | U28: =LOOKUP(DATE($O28,U$25,U$24),$A$2:$A$2943,$H$2:$H$2943) | V28: =LOOKUP(DATE($O28,V$25,V$24),$A$2:$A$2943,$H$2:$H$2943) | W28: =LOOKUP(DATE($O28,W$25,W$24),$A$2:$A$2943,$H$2:$H$2943) | ... AA28: =LOOKUP(DATE($O28,AA$25,AA$24),$A$2:$A$2943,$H$2:$H$2943) | AD28: 2016 | AW28: Rentabilidad | AX28: Mensual | AY28: Trimestral | AZ28: Semestral | BA28: Anual | BB28: Acum. 2025
A29: 39478 | B29: 12223.14 | C29: =(B29/B28-1)/(A29-A28)*30 | O29: 2018 | P29: =LOOKUP(DATE($O29,P$25,P$24),$A$2:$A$2943,$H$2:$H$2943) | Q29: =LOOKUP(DATE($O29,Q$25,Q$24),$A$2:$A$2943,$H$2:$H$2943) | R29: =LOOKUP(DATE($O29,R$25,R$24),$A$2:$A$2943,$H$2:$H$2943) | S29: =LOOKUP(DATE($O29,S$25,S$24),$A$2:$A$2943,$H$2:$H$2943) | T29: =LOOKUP(DATE($O29,T$25,T$24),$A$2:$A$2943,$H$2:$H$2943) | U29: =LOOKUP(DATE($O29,U$25,U$24),$A$2:$A$2943,$H$2:$H$2943) | V29: =LOOKUP(DATE($O29,V$25,V$24),$A$2:$A$2943,$H$2:$H$2943) | W29: =LOOKUP(DATE($O29,W$25,W$24),$A$2:$A$2943,$H$2:$H$2943) | ... AA29: =LOOKUP(DATE($O29,AA$25,AA$24),$A$2:$A$2943,$H$2:$H$2943) | AD29: 2017 | AR29: (*) | AW29: ICP (Bechmark) | AX29: =$AW20/AX20-1 | AY29: =$AW20/AY20-1 | AZ29: =$AW20/AZ20-1 | BA29: =$AW20/BA20-1 | BB29: =+AQ86
A30: 39507 | B30: 12284.88 | C30: =(B30/B29-1)/(A30-A29)*30 | O30: 2019 | P30: =LOOKUP(DATE($O30,P$25,P$24),$A$2:$A$2943,$H$2:$H$2943) | Q30: =LOOKUP(DATE($O30,Q$25,Q$24),$A$2:$A$2943,$H$2:$H$2943) | R30: =LOOKUP(DATE($O30,R$25,R$24),$A$2:$A$2943,$H$2:$H$2943) | S30: =LOOKUP(DATE($O30,S$25,S$24),$A$2:$A$2943,$H$2:$H$2943) | T30: =LOOKUP(DATE($O30,T$25,T$24),$A$2:$A$2943,$H$2:$H$2943) | U30: =LOOKUP(DATE($O30,U$25,U$24),$A$2:$A$2943,$H$2:$H$2943) | V30: =LOOKUP(DATE($O30,V$25,V$24),$A$2:$A$2943,$H$2:$H$2943) | W30: =LOOKUP(DATE($O30,W$25,W$24),$A$2:$A$2943,$H$2:$H$2943) | ... AA30: =LOOKUP(DATE($O30,AA$25,AA$24),$A$2:$A$2943,$H$2:$H$2943) | AD30: 2018 | AW30: Competencia | AX30: =$AW21/AX21-1 | AY30: =$AW21/AY21-1 | AZ30: =$AW21/AZ21-1 | BA30: =$AW21/BA21-1 | BB30: =+AQ87
A31: 39538 | B31: 12351.45 | C31: =(B31/B30-1)/(A31-A30)*30 | O31: 2020 | P31: =LOOKUP(DATE($O31,P$25,P$24),$A$2:$A$2943,$H$2:$H$2943) | Q31: =LOOKUP(DATE($O31,Q$25,Q$24)+1,$A$2:$A$2943,$H$2:$H$2943) | R31: =LOOKUP(DATE($O31,R$25,R$24)+1,$A$2:$A$2943,$H$2:$H$2943) | S31: =LOOKUP(DATE($O31,S$25,S$24)+1,$A$2:$A$2943,$H$2:$H$2943) | T31: =LOOKUP(DATE($O31,T$25,T$24)+1,$A$2:$A$2943,$H$2:$H$2943) | U31: =LOOKUP(DATE($O31,U$25,U$24)+1,$A$2:$A$2943,$H$2:$H$2943) | V31: =LOOKUP(DATE($O31,V$25,V$24)+1,$A$2:$A$2943,$H$2:$H$2943) | W31: =LOOKUP(DATE($O31,W$25,W$24)+1,$A$2:$A$2943,$H$2:$H$2943) | X31: =LOOKUP(DATE($O31,X$25,X$24)+1,$A$2:$A$2943,$H$2:$H$2943) | Y31: =+H183 | Z31: =+H184 | AA31: =+H185 | AD31: 2019 | AW31: FIP LIQUIDEZ FLEXIBLE | AX31: =$AW22/AX22-1 | AY31: =IFERROR($AW22/AY22-1,0) | AZ31: =IFERROR($AW22/AZ22-1,0) | BA31: =$AW22/BA22-1 | BB31: =+AQ88
A32: 39568 | B32: 12416.18 | C32: =(B32/B31-1)/(A32-A31)*30 | O32: 2021 | AD32: 2020
A33: 39598 | B33: 12481.48 | C33: =(B33/B32-1)/(A33-A32)*30 | O33: 2022 | AD33: 2021
A34: 39629 | B34: 12552.23 | C34: =(B34/B33-1)/(A34-A33)*30 | O34: 2023 | AD34: 2022
A35: 39660 | B35: 12628.9 | C35: =(B35/B34-1)/(A35-A34)*30 | O35: 2024 | AD35: 2023
A36: 39689 | B36: 12704.63 | C36: =(B36/B35-1)/(A36-A35)*30 | O36: 2025 | P36: 1000 | Q36: 1000 | R36: 1000 | S36: =+H237 | T36: =+H238 | U36: =+H239 | V36: =+H240 | W36: =+H241 | X36: =+H242 | Y36: =+H243 | Z36: =+H244 | AA36: =+H245 | AD36: 2024
O37: 2026 | P37: =$H246 | Q37: =$H247 | R37: =$H248 | S37: =$H249 | AD37: 2025 | AE37: 0 | AF37: =+(Q36/P36-1) | AG37: =+(R36/Q36-1) | AH37: =+(S36/R36-1) | AI37: =+(T36/S36-1) | AJ37: =+(U36/T36-1) | AK37: =+(V36/U36-1) | AL37: =+(W36/V36-1) | AM37: =+(X36/W36-1) | ... AP37: =+(AA36/Z36-1) | AQ37: =+(AA36/R36-1)/COUNTA(AE37:AP37)*12
A38: 39721 | B38: 12796.95 | C38: =(B38/B36-1)/(A38-A36)*30 | P38: 31 | Q38: 28 | R38: 31 | S38: 30 | T38: 31 | U38: 30 | V38: 31 | W38: 31 | X38: 30 | Y38: 31 | Z38: 30 | AA38: 31 | AD38: 2026 | AE38: =+(P37/AA36-1) | AF38: =+(Q37/P37-1) | AG38: =+(R37/Q37-1) | AH38: =+(S37/R37-1) | AQ38: =+(R37/AA36-1)/COUNTA(AE38:AP38)*12 | AR38: (*)
A39: 39752 | B39: 12885.37 | C39: =(B39/B38-1)/(A39-A38)*30 | P39: 1 | Q39: 2 | R39: 3 | S39: 4 | T39: 5 | U39: 6 | V39: 7 | W39: 8 | X39: 9 | Y39: 10 | Z39: 11 | AA39: 12 | AD39: (*) Acum a Mar
A40: 39780 | B40: 12970.93 | C40: =(B40/B39-1)/(A40-A39)*30 | O40: Competencia | P40: Ene | Q40: Feb | R40: Mar | S40: Abr | T40: May | U40: Jun | V40: Jul | W40: Ago | X40: Sep | Y40: Oct | Z40: Nov | AA40: Dic | AD40: Competencia | AE40: Ene | AF40: Feb | AG40: Mar | AH40: Abr | AI40: May | AJ40: Jun | AK40: Jul | AL40: Ago | AM40: Sep | AN40: Oct | AO40: Nov | AP40: Dic | AQ40: Total Año
...

Sheet rentabilidad
S1: Rentabilidad | T1: Mensual | U1: Trimestral | V1: Semestral | W1: Anual | X1: =+'Datos ICP (2)'!BB28
S2: ICP (Benchmark) | T2: =+'Datos ICP (2)'!AX29 | U2: =+'Datos ICP (2)'!AY29 | V2: =+'Datos ICP (2)'!AZ29 | W2: =+'Datos ICP (2)'!BA29 | X2: =+'Datos ICP (2)'!BB29
S3: Competencia | T3: =+'Datos ICP (2)'!AX30 | U3: =+'Datos ICP (2)'!AY30 | V3: =+'Datos ICP (2)'!AZ30 | W3: =+'Datos ICP (2)'!BA30 | X3: =+'Datos ICP (2)'!BB30
S4: FIP LIQUIDEZ FLEXIBLE | T4: =+'Datos ICP (2)'!AX31 | U4: ='Datos ICP (2)'!AY31 | V4: =+'Datos ICP (2)'!AZ31 | W4: =+'Datos ICP (2)'!BA31 | X4: =+'Datos ICP (2)'!BB31
C6: Año | D6: Fondo | E6: Ene | F6: Feb | G6: Mar | H6: Abr | I6: May | J6: Jun | K6: Jul | L6: Ago | M6: Sep | N6: Oct | O6: Nov | P6: Dic | Q6: Total Año
C8: 2013 | D8: ICP
C9: 2014 | D9: ICP
C10: 2015 | D10: ICP
C11: 2016 | D11: ICP
C12: 2017 | D12: ICP
D13: Competencia
D14: FIP LIQUIDEZ Temporal
C15: 2018 | D15: ICP
D16: Competencia
D17: FIP LIQUIDEZ Temporal
C18: 2019 | D18: ICP
D19: Competencia
D20: FIP LIQUIDEZ Temporal
C21: 2020 | D21: ICP
D22: Competencia
D23: FIP LIQUIDEZ Temporal
C24: 2021 | D24: ICP
D25: Competencia
D26: FIP LIQUIDEZ Temporal
C27: 2022 | D27: ICP
D28: Competencia
D29: FIP LIQUIDEZ Temporal
C30: 2023 | D30: ICP | M30: =+'Datos ICP (2)'!AM77 | N30: =+'Datos ICP (2)'!AN77 | O30: =+'Datos ICP (2)'!AO77 | P30: =+'Datos ICP (2)'!AP77 | Q30: =+'Datos ICP (2)'!AQ77
D31: Competencia | M31: =+'Datos ICP (2)'!AM78 | N31: =+'Datos ICP (2)'!AN78 | O31: =+'Datos ICP (2)'!AO78 | P31: =+'Datos ICP (2)'!AP78 | Q31: =+'Datos ICP (2)'!AQ78
D32: FIP LIQUIDEZ Temporal | M32: =+'Datos ICP (2)'!AM79 | N32: =+'Datos ICP (2)'!AN79 | O32: =+'Datos ICP (2)'!AO79 | P32: =+'Datos ICP (2)'!AP79 | Q32: =+'Datos ICP (2)'!AQ79
C33: 2024 | D33: ICP | E33: =+'Datos ICP (2)'!AE80 | F33: =+'Datos ICP (2)'!AF80 | G33: =+'Datos ICP (2)'!AG80 | H33: =+'Datos ICP (2)'!AH80 | I33: =+'Datos ICP (2)'!AI80 | J33: =+'Datos ICP (2)'!AJ80 | K33: =+'Datos ICP (2)'!AK80 | L33: =+'Datos ICP (2)'!AL80 | ... Q33: =+'Datos ICP (2)'!AQ80
D34: Competencia | E34: =+'Datos ICP (2)'!AE81 | F34: =+'Datos ICP (2)'!AF81 | G34: =+'Datos ICP (2)'!AG81 | H34: =+'Datos ICP (2)'!AH81 | I34: =+'Datos ICP (2)'!AI81 | J34: =+'Datos ICP (2)'!AJ81 | K34: =+'Datos ICP (2)'!AK81 | L34: =+'Datos ICP (2)'!AL81 | ... Q34: =+'Datos ICP (2)'!AQ81
D35: FIP LIQUIDEZ Temporal | E35: =+'Datos ICP (2)'!AE82 | F35: =+'Datos ICP (2)'!AF82 | G35: =+'Datos ICP (2)'!AG82 | H35: =+'Datos ICP (2)'!AH82 | I35: =+'Datos ICP (2)'!AI82 | J35: =+'Datos ICP (2)'!AJ82 | K35: =+'Datos ICP (2)'!AK82 | L35: =+'Datos ICP (2)'!AL82 | ... Q35: =+'Datos ICP (2)'!AQ82
C36: 2025 | D36: ICP | E36: =+'Datos ICP (2)'!AE83 | F36: =+'Datos ICP (2)'!AF83 | G36: =+'Datos ICP (2)'!AG83 | H36: =+'Datos ICP (2)'!AH83 | I36: =+'Datos ICP (2)'!AI83 | J36: =+'Datos ICP (2)'!AJ83 | K36: =+'Datos ICP (2)'!AK83 | L36: =+'Datos ICP (2)'!AL83 | ... Q36: =+'Datos ICP (2)'!AQ83
D37: Competencia | E37: =+'Datos ICP (2)'!AE84 | F37: =+'Datos ICP (2)'!AF84 | G37: =+'Datos ICP (2)'!AG84 | H37: =+'Datos ICP (2)'!AH84 | I37: =+'Datos ICP (2)'!AI84 | J37: =+'Datos ICP (2)'!AJ84 | K37: =+'Datos ICP (2)'!AK84 | L37: =+'Datos ICP (2)'!AL84 | ... Q37: =+'Datos ICP (2)'!AQ84
D38: FIP LIQUIDEZ Temporal | E38: =+'Datos ICP (2)'!AE85 | F38: =+'Datos ICP (2)'!AF85 | G38: =+'Datos ICP (2)'!AG85 | H38: =+'Datos ICP (2)'!AH85 | I38: =+'Datos ICP (2)'!AI85 | J38: =+'Datos ICP (2)'!AJ85 | K38: =+'Datos ICP (2)'!AK85 | L38: =+'Datos ICP (2)'!AL85 | ... Q38: =+'Datos ICP (2)'!AQ85
C39: 2026 | D39: ICP | E39: =+'Datos ICP (2)'!AE86 | F39: =+'Datos ICP (2)'!AF86 | G39: =+'Datos ICP (2)'!AG86 | H39: =+'Datos ICP (2)'!AH86 | Q39: =+'Datos ICP (2)'!AQ86
D40: Competencia | E40: =+'Datos ICP (2)'!AE87 | F40: =+'Datos ICP (2)'!AF87 | G40: =+'Datos ICP (2)'!AG87 | H40: =+'Datos ICP (2)'!AH87 | Q40: =+'Datos ICP (2)'!AQ87
D41: FIP LIQUIDEZ Temporal | E41: =+'Datos ICP (2)'!AE88 | F41: =+'Datos ICP (2)'!AF88 | G41: =+'Datos ICP (2)'!AG88 | H41: =+'Datos ICP (2)'!AH88 | Q41: =+'Datos ICP (2)'!AQ88

Sheet composición
J1: Duración | N1: Instrumentos | R1: Moneda
O2: Bono | P2: 0
K3: Menos de 1 mes | L3: 0.529 | O3: Depósitos | P3: 0 | S3: Pesos | T3: 1
K4: 1-3 meses | L4: 0.4679 | O4: Factoring | P4: 0 | S4: UF | T4: 0
K5: 3-4 meses | L5: 0 | O5: Financiamiento Inmobiliario | P5: 0.1185
K6: Más de 4 meses | L6: 0 | O6: Financiamiento Mesa Moneda Extranjera | P6: 0.799
L7: =SUM(L3:L6) | O7: Garantías | P7: 0
O8: Nota Estructurada | P8: 0.0825
O9: Financiamiento Mesa Renta Fija | P9: 0
O10: Simultánea | P10: 0
O11: Efectos de Comercio | P11: 0
O13: Pagaré | P13: 0
A14: Facturas | B14: 0
P15: =SUM(P2:P14)
