Workbook

Sheet Comentario
A2: La variación del IPC del mes de Enero fue de 1,10% que fue muy por sobre de las expectativas de mercado y la variación en 12 meses quedó, en 4,90%. Este IPC muestra que la situación todavía no está controlada, El BC tiene que evaluar muy bien las medidas a seguir, por lo pronto no deberían seguir bajando la TPM hasta que tenga datos más positivos de Inflación. Los depósitos a plazo (IIF) no reflejan movimientos de tasa por todo el año por parte del emisor.

Sheet Datos ICP (2)
A1: CLICP Index | F1: Cuota Liquidez Monetario | AD1: ICP | AE1: Ene | AF1: Feb | AG1: Mar | AH1: Abr | AI1: May | AJ1: Jun | AK1: Jul | AL1: Ago | AM1: Sep | AN1: Oct | AO1: Nov | AP1: Dic | AQ1: Total Año
A2: Fecha | B2: ICP | D2: ICP Norm. | J2: Fondo Liquidez Monetario | K2: 8057-8 | M2: Competencia Relevante (*) | P2: Ene | Q2: Feb | R2: Mar | S2: Abr | T2: May | U2: Jun | V2: Jul | W2: Ago | X2: Sep | Y2: Oct | Z2: Nov | AA2: Dic | AD2: 2006 | AE2: =P3/N3-1 | AF2: =Q3/P3-1 | AG2: =R3/Q3-1 | AH2: =S3/R3-1 | AI2: =T3/S3-1 | AJ2: =U3/T3-1 | AK2: =V3/U3-1 | AL2: =W3/V3-1 | AM2: =X3/W3-1 | ... AP2: =AA3/Z3-1 | AQ2: =AA3/N3-1
A3: 38717 | B3: 10953.14 | D3: =B3/$B$3*100 | N3: =B3 | O3: 2006 | P3: 10996.85 | Q3: 11035.11 | R3: 11078.66 | S3: 11118.82 | T3: 11169.1 | U3: 11215.04 | V3: 11263.22 | W3: 11313.29 | X3: 11360.92 | Y3: 11413.02 | Z3: 11463.01 | AA3: 11512.49 | AD3: 2007 | AE3: =P4/AA3-1 | AF3: =Q4/P4-1 | AG3: =R4/Q4-1 | AH3: =S4/R4-1 | AI3: =T4/S4-1 | AJ3: =U4/T4-1 | AK3: =V4/U4-1 | AL3: =W4/V4-1 | AM3: =X4/W4-1 | ... AP3: =AA4/Z4-1 | AQ3: =AA4/AA3-1
A4: 38748 | B4: 10996.85 | C4: =(B4/B3-1)/(A4-A3)*30 | D4: =B4/$B$3*100 | K4: Sant. Money Market UNIV | O4: 2007 | P4: 11567.23 | Q4: 11612.68 | R4: 11661.5 | S4: 11712.58 | T4: 11763.78 | U4: 11812.23 | V4: 11866.53 | W4: 11922.48 | X4: 11975.61 | Y4: 12038.9 | Z4: 12096.85 | AA4: 12152.6 | AD4: 2008 | AE4: =P5/AA4-1 | AF4: =Q5/P5-1 | AG4: =R5/Q5-1 | AH4: =S5/R5-1 | AI4: =T5/S5-1 | AJ4: =U5/T5-1 | AK4: =V5/U5-1 | AL4: =W5/V5-1 | AM4: =X5/W5-1 | ... AP4: =AA5/Z5-1 | AQ4: =AA5/AA4-1
A5: 38776 | B5: 11035.11 | C5: =(B5/B4-1)/(A5-A4)*30 | D5: =B5/$B$3*100 | O5: 2008 | P5: 12223.14 | Q5: 12284.88 | R5: 12351.45 | S5: 12416.18 | T5: 12481.48 | U5: 12552.23 | V5: 12628.9 | W5: 12704.63 | X5: 12796.95 | Y5: 12885.37 | Z5: 12970.93 | AA5: 13066.33 | AD5: 2009 | AE5: =P6/AA5-1 | AF5: =Q6/P6-1 | AG5: =R6/Q6-1 | AH5: =S6/R6-1 | AI5: =T6/S6-1 | AJ5: =U6/T6-1 | AK5: =V6/U6-1 | AL5: =W6/V6-1 | AM5: =X6/W6-1 | ... AP5: =AA6/Z6-1 | AQ5: =AA6/AA5-1
A6: 38807 | B6: 11078.66 | C6: =(B6/B5-1)/(A6-A5)*30 | D6: =B6/$B$3*100 | O6: 2009 | P6: 13151.16 | Q6: 13212.09 | R6: 13251.18 | S6: 13272.62 | T6: 13286.96 | U6: 13299.08 | V6: 13305.34 | W6: 13310.07 | X6: 13315.05 | Y6: 13319.74 | Z6: 13324.51 | AA6: 13329.5 | AD6: 2010 | AE6: =P7/AA6-1 | AF6: =Q7/P7-1 | AG6: =R7/Q7-1 | AH6: =S7/R7-1 | AI6: =T7/S7-1 | AJ6: =U7/T7-1 | AK6: =V7/U7-1 | AL6: =W7/V7-1 | AM6: =X7/W7-1 | ... AP6: =AA7/Z7-1 | AQ6: =AA7/AA6-1
A7: 38835 | B7: 11118.82 | C7: =(B7/B6-1)/(A7-A6)*30 | D7: =B7/$B$3*100 | O7: 2010 | P7: 13334.25 | Q7: 13338.53 | R7: 13343.79 | S7: 13348.63 | T7: 13353.5 | U7: 13360.9 | V7: 13373.99 | W7: 13395.21 | X7: 13419.79 | Y7: 13448.69 | Z7: 13483.02 | AA7: 13522.93 | AD7: 2011 | AE7: =P8/AA7-1 | AF7: =Q8/P8-1 | AG7: =R8/Q8-1 | AH7: =S8/R8-1 | AI7: =T8/S8-1 | AJ7: =U8/T8-1 | AK7: =V8/U8-1 | AL7: =W8/V8-1 | AM7: =X8/W8-1 | ... AP7: =AA8/Z8-1 | AQ7: =AA8/AA7-1
A8: 38868 | B8: 11169.1 | C8: =(B8/B7-1)/(A8-A7)*30 | D8: =B8/$B$3*100 | O8: 2011 | P8: 13557.12 | Q8: 13592.3 | R8: 13635.91 | S8: 13682.94 | T8: 13741.06 | U8: 13799.74 | V8: 13858.14 | W8: 13925.03 | X8: 13985.97 | Y8: 14043.21 | Z8: 14110.87 | AA8: 14172.63 | AD8: 2012 | AE8: =P9/AA8-1 | AF8: =Q9/P9-1 | AG8: =R9/Q9-1 | AH8: =S9/R9-1 | AI8: =T9/S9-1 | AJ8: =U9/T9-1 | AK8: =V9/U9-1 | AL8: =W9/V9-1 | AM8: =X9/W9-1 | ... AP8: =AA9/Z9-1 | AQ8: =AA9/AA8-1
A9: 38898 | B9: 11215.04 | C9: =(B9/B8-1)/(A9-A8)*30 | D9: =B9/$B$3*100 | O9: 2012 | P9: 14236.38 | Q9: 14293.67 | R9: 14353.34 | S9: 14415.21 | T9: 14477.55 | U9: 14536.13 | V9: 14600.61 | W9: 14663.33 | X9: 14720.68 | Y9: 14788.56 | Z9: 14850.38 | AA9: 14908.2 | AD9: 2013 | AE9: =P10/AA9-1 | AF9: =Q10/P10-1 | AG9: =R10/Q10-1 | AH9: =S10/R10-1 | AI9: =T10/S10-1 | AJ9: =U10/T10-1 | AK9: =V10/U10-1 | AL9: =W10/V10-1 | AM9: =X10/W10-1 | ... AP9: =AA10/Z10-1 | AQ9: =AA10/AA9-1
A10: 38929 | B10: 11263.22 | C10: =(B10/B9-1)/(A10-A9)*30 | D10: =B10/$B$3*100 | O10: 2013 | P10: 14978.58 | Q10: 15036.94 | R10: 15095.51 | S10: 15164.77 | T10: 15230.38 | U10: 15289.74 | V10: 15360.27 | W10: 15424.43 | X10: 15490.99 | Y10: 15554.36 | Z10: 15615.06 | AA10: 15675.68 | AD10: 2014 | AE10: =P11/AA10-1 | AF10: =Q11/P11-1 | AG10: =R11/Q11-1 | AH10: =S11/R11-1 | AI10: =T11/S11-1 | AJ10: =U11/T11-1 | AK10: =V11/U11-1 | AL10: =W11/V11-1 | AM10: =X11/W11-1 | ... AP10: =AA11/Z11-1 | AQ10: =AA11/AA10-1
A11: 38960 | B11: 11313.29 | C11: =(B11/B10-1)/(A11-A10)*30 | D11: =B11/$B$3*100 | O11: 2014 | P11: 15738.45 | Q11: 15792.47 | R11: 15848.53 | S11: 15901.43 | T11: 15954.5 | U11: 16009.53 | V11: 16063.18 | W11: 16110.55 | X11: 16158.37 | Y11: 16200.86 | Z11: 16240.11 | AA11: 16283.49 | AD11: 2015 | AE11: =P12/AA11-1 | AF11: =Q12/P12-1 | AG11: =R12/Q12-1 | AH11: =S12/R12-1 | AI11: =T12/S12-1 | AJ11: =U12/T12-1 | AK11: =V12/U12-1 | AL11: =W12/V12-1 | AM11: =X12/W12-1 | ... AP11: =AA12/Z12-1 | AQ11: =AA12/AA11-1
A12: 38989 | B12: 11360.92 | C12: =(B12/B11-1)/(A12-A11)*30 | D12: =B12/$B$3*100 | O12: 2015 | P12: 16325.65 | Q12: 16363.77 | R12: 16407.49 | S12: 16448.59 | T12: 16488.37 | U12: 16532.38 | V12: 16575.11 | W12: 16617.94 | X12: 16659.58 | Y12: 16702.94 | Z12: 16749.75 | AA12: 16796.52 | AD12: 2016 | AE12: =P13/AA12-1 | AF12: =Q13/P13-1 | AG12: =R13/Q13-1 | AH12: =S13/R13-1 | AI12: =T13/S13-1 | AJ12: =U13/T13-1 | AK12: =V13/U13-1 | AL12: =W13/V13-1 | AM12: =X13/W13-1 | ... AP12: =AA13/Z13-1 | AQ12: =AA13/AA12-1
A13: 39021 | B13: 11413.02 | C13: =(B13/B12-1)/(A13-A12)*30 | D13: =B13/$B$3*100 | O13: 2016 | P13: 16845.59 | Q13: 16896.43 | R13: 16947.43 | S13: 16995.27 | T13: 17048.23 | U13: 17098.02 | V13: 17149.62 | W13: 17201.38 | X13: 17251.69 | Y13: =+B133 | Z13: =+B134 | AA13: =+B135 | AD13: 2017 | AE13: =P14/AA13-1 | AF13: =+Q14/P14-1 | AG13: =+R14/Q14-1 | AH13: =+S14/R14-1 | AI13: =+T14/S14-1 | AJ13: =+U14/T14-1 | AK13: =+V14/U14-1 | AL13: =+W14/V14-1 | AM13: =+X14/W14-1 | ... AP13: =+AA14/Z14-1 | AQ13: =AA14/AA13-1
A14: 39051 | B14: 11463.01 | C14: =(B14/B13-1)/(A14-A13)*30 | D14: =B14/$B$3*100 | O14: 2017 | P14: =+B136 | Q14: =+B137 | R14: =+B138 | S14: =+B139 | T14: =+B140 | U14: =+$B141 | V14: =+$B142 | W14: =+$B143 | X14: =+$B144 | Y14: =+$B145 | Z14: =+$B146 | AA14: =+$B147 | AD14: 2018 | AE14: =P15/AA14-1 | AF14: =+Q15/P15-1 | AG14: =+R15/Q15-1 | AH14: =+S15/R15-1 | AI14: =+T15/S15-1 | AJ14: =+U15/T15-1 | AK14: =+V15/U15-1 | AL14: =+W15/V15-1 | AM14: =+X15/W15-1 | ... AP14: =+AA15/Z15-1 | AQ14: =+AA15/AA14-1
A15: 39080 | B15: 11512.49 | C15: =(B15/B14-1)/(A15-A14)*30 | D15: =B15/$B$3*100 | O15: 2018 | P15: =+B148 | Q15: =+B149 | R15: =+B150 | S15: =+B151 | T15: =+B152 | U15: =+B153 | V15: =+B154 | W15: =+B155 | X15: =+B156 | Y15: =+B157 | Z15: =+B158 | AA15: =+B159 | AD15: 2019 | AE15: =+P16/AA15-1 | AF15: =+Q16/P16-1 | AG15: =+R16/Q16-1 | AH15: =+S16/R16-1 | AI15: =+T16/S16-1 | AJ15: =+U16/T16-1 | AK15: =+V16/U16-1 | AL15: =+W16/V16-1 | AM15: =+X16/W16-1 | ... AP15: =+AA16/Z16-1 | AQ15: =+(AA16/AA15-1)/COUNTA(AE15:AP15)*12 | AR15: (*)
A16: 39113 | B16: 11567.23 | C16: =(B16/B15-1)/(A16-A15)*30 | D16: =B16/$B$3*100 | O16: 2019 | P16: =+B160 | Q16: =+B161 | R16: =+B162 | S16: =+B163 | T16: =+B164 | U16: =+B165 | V16: =+B166 | W16: =+B167 | X16: =+B168 | Y16: =+B169 | Z16: =+B170 | AA16: =+B171 | AD16: 2020 | AE16: =+P17/AA16-1 | AF16: =+Q17/P17-1 | AG16: =+R17/Q17-1 | AH16: =+S17/R17-1 | AI16: =+T17/S17-1 | AJ16: =+U17/T17-1 | AK16: =+V17/U17-1 | AL16: =+W17/V17-1 | AM16: =+X17/W17-1 | ... AP16: =+AA17/Z17-1 | AQ16: =+(AA17/AA16-1)/COUNTA(AE16:AP16)*12
A17: 39141 | B17: 11612.68 | C17: =(B17/B16-1)/(A17-A16)*30 | D17: =B17/$B$3*100 | O17: 2020 | P17: =+B172 | Q17: =+B173 | R17: =+B174 | S17: =+B175 | T17: =+B176 | U17: =+B177 | V17: =+B178 | W17: =+B179 | X17: =+B180 | Y17: =+B181 | Z17: =+B182 | AA17: =+B183 | AD17: 2021 | AE17: =+P18/AA17-1 | AF17: =+Q18/P18-1 | AG17: =+R18/Q18-1 | AH17: =+S18/R18-1 | AI17: =+T18/S18-1 | AJ17: =+U18/T18-1 | AK17: =+V18/U18-1 | AL17: =+W18/V18-1 | AM17: =+X18/W18-1 | ... AP17: =+AA18/Z18-1 | AQ17: =+(AA18/AA17-1)/COUNTA(AE17:AP17)*12
A18: 39171 | B18: 11661.5 | C18: =(B18/B17-1)/(A18-A17)*30 | D18: =B18/$B$3*100 | O18: 2021 | P18: =+B184 | Q18: =+B185 | R18: =+B186 | S18: =+B187 | T18: =+B188 | U18: =+B189 | V18: =+B190 | W18: =+B191 | X18: =+B192 | Y18: =+B193 | Z18: =+B194 | AA18: =+B195 | AD18: 2022 | AE18: =+P19/AA18-1 | AF18: =+Q19/P19-1 | AG18: =+R19/Q19-1 | AH18: =+S19/R19-1 | AI18: =+T19/S19-1 | AJ18: =+U19/T19-1 | AK18: =+V19/U19-1 | AL18: =+W19/V19-1 | AM18: =+X19/W19-1 | ... AP18: =+AA19/Z19-1 | AQ18: =+(AA19/AA18-1)/COUNTA(AE18:AP18)*12 | AX18: -1 | AY18: -3 | AZ18: -6 | BA18: -12
A19: 39202 | B19: 11712.58 | C19: =(B19/B18-1)/(A19-A18)*30 | D19: =B19/$B$3*100 | O19: 2022 | P19: =+B196 | Q19: =+B197 | R19: =+B198 | S19: =+B199 | T19: =+B200 | U19: =+B201 | V19: =+B202 | W19: =+B203 | X19: =+B204 | Y19: =+B205 | Z19: =+B206 | AA19: =+B207 | AD19: 2023 | AE19: =+P20/AA19-1 | AF19: =+Q20/P20-1 | AG19: =+R20/Q20-1 | AH19: =+S20/R20-1 | AI19: =+T20/S20-1 | AJ19: =+U20/T20-1 | AK19: =+V20/U20-1 | AL19: =+W20/V20-1 | AM19: =+X20/W20-1 | ... AP19: =+AA20/Z20-1 | AQ19: =+(AA20/AA19-1)/COUNTA(AE19:AP19)*12 | AV19: Ingresar mes actual==> | AW19: 46144 | AX19: =EOMONTH($AW19,AX18) | AY19: =EOMONTH($AW19,AY18) | AZ19: =EOMONTH($AW19,AZ18) | BA19: =EOMONTH($AW19,BA18) | BB19: 43465
A20: 39233 | B20: 11763.78 | C20: =(B20/B19-1)/(A20-A19)*30 | D20: =B20/$B$3*100 | O20: 2023 | P20: =+B208 | Q20: =+B209 | R20: =+B210 | S20: =+B211 | T20: =+B212 | U20: =+B213 | V20: =+B214 | W20: =+B215 | X20: =+B216 | Y20: =+B217 | Z20: =+B218 | AA20: =+B219 | AD20: 2024 | AE20: =+P21/AA20-1 | AF20: =+Q21/P21-1 | AG20: =+R21/Q21-1 | AH20: =+S21/R21-1 | AI20: =+T21/S21-1 | AJ20: =+U21/T21-1 | AK20: =+V21/U21-1 | AL20: =+W21/V21-1 | AM20: =+X21/W21-1 | ... AP20: =+AA21/Z21-1 | AQ20: =+(AA21/AA20-1)/COUNTA(AE20:AP20)*12 | AV20: ICP | AW20: =LOOKUP(AW19,$A$3:$A$2971,$B$3:$B$2971) | AX20: =LOOKUP(AX19,$A$3:$A$2971,$B$3:$B$2971) | AY20: =LOOKUP(AY19,$A$3:$A$2971,$B$3:$B$2971) | AZ20: =LOOKUP(AZ19,$A$3:$A$2971,$B$3:$B$2971) | BA20: =LOOKUP(BA19,$A$3:$A$2971,$B$3:$B$2971) | BB20: =LOOKUP(BB19,$A$3:$A$2971,$B$3:$B$2971)
A21: 39262 | B21: 11812.23 | C21: =(B21/B20-1)/(A21-A20)*30 | D21: =B21/$B$3*100 | O21: 2024 | P21: =+B220 | Q21: =+B221 | R21: =+B222 | S21: =+B223 | T21: =+B224 | U21: =+B225 | V21: =+B226 | W21: =+B227 | X21: =+B228 | Y21: =+B229 | Z21: =+B230 | AA21: =+B231 | AD21: 2025 | AE21: =+P22/AA21-1 | AQ21: =+(P22/AA21-1)/COUNTA(AE21:AP21)*12 | AV21: Competencia | AW21: =LOOKUP(AW19,$F$2:$F$2972,$K$2:$K$2972) | AX21: =LOOKUP(AX19,$F$2:$F$2972,$K$2:$K$2972) | AY21: =LOOKUP(AY19,$F$2:$F$2972,$K$2:$K$2972) | AZ21: =LOOKUP(AZ19,$F$2:$F$2972,$K$2:$K$2972) | BA21: =LOOKUP(BA19,$F$2:$F$2972,$K$2:$K$2972) | BB21: =LOOKUP(BB19,$F$2:$F$2972,$K$2:$K$2972)
A22: 39294 | B22: 11866.53 | C22: =(B22/B21-1)/(A22-A21)*30 | D22: =B22/$B$3*100 | O22: 2025 | P22: =+B232 | AD22: (*) Acum a Mar | AV22: FIP Monetario | AW22: =LOOKUP(AW19,$F$2:$F$2970,$H$2:$H$2970) | AX22: =LOOKUP(AX19,$F$2:$F$2970,$H$2:$H$2970) | AY22: =LOOKUP(AY19,$F$2:$F$2970,$H$2:$H$2970) | AZ22: =LOOKUP(AZ19,$F$2:$F$2970,$H$2:$H$2970) | BA22: =LOOKUP(BA19,$F$2:$F$2970,$H$2:$H$2970) | BB22: =LOOKUP(BB19,$F$2:$F$2972,$H$2:$H$2972)
A23: 39325 | B23: 11922.48 | C23: =(B23/B22-1)/(A23-A22)*30 | D23: =B23/$B$3*100 | P23: 31 | Q23: 28 | R23: 31 | S23: 30 | T23: 31 | U23: 30 | V23: 31 | W23: 31 | X23: 30 | Y23: 31 | Z23: 30 | AA23: 31
A24: 39353 | B24: 11975.61 | C24: =(B24/B23-1)/(A24-A23)*30 | D24: =B24/$B$3*100 | P24: 1 | Q24: 2 | R24: 3 | S24: 4 | T24: 5 | U24: 6 | V24: 7 | W24: 8 | X24: 9 | Y24: 10 | Z24: 11 | AA24: 12
A25: 39386 | B25: 12038.9 | C25: =(B25/B24-1)/(A25-A24)*30 | D25: =B25/$B$3*100 | O25: FONDO LIQUIDEZ MONETARIO | P25: Ene | Q25: Feb | R25: Mar | S25: Abr | T25: May | U25: Jun | V25: Jul | W25: Ago | X25: Sep | Y25: Oct | Z25: Nov | AA25: Dic
A26: 39416 | B26: 12096.85 | C26: =(B26/B25-1)/(A26-A25)*30 | D26: =B26/$B$3*100 | O26: 2016 | U26: =LOOKUP(DATE($O26,U$24,U$23),$A$2:$A$2941,$H$2:$H$2941) | V26: =LOOKUP(DATE($O26,V$24,V$23),$A$2:$A$2941,$H$2:$H$2941) | W26: =LOOKUP(DATE($O26,W$24,W$23),$A$2:$A$2941,$H$2:$H$2941) | X26: =LOOKUP(DATE($O26,X$24,X$23),$A$2:$A$2941,$H$2:$H$2941) | Y26: =LOOKUP(DATE($O26,Y$24,Y$23),$A$2:$A$2941,$H$2:$H$2941) | Z26: =LOOKUP(DATE($O26,Z$24,Z$23),$A$2:$A$2941,$H$2:$H$2941) | AA26: =LOOKUP(DATE($O26,AA$24,AA$23),$A$2:$A$2941,$H$2:$H$2941) | AD26: Monetario | AE26: Ene | AF26: Feb | AG26: Mar | AH26: Abr | AI26: May | AJ26: Jun | AK26: Jul | AL26: Ago | AM26: Sep | AN26: Oct | AO26: Nov | AP26: Dic | AQ26: Total Año
A27: 39447 | B27: 12152.6 | C27: =(B27/B26-1)/(A27-A26)*30 | D27: =B27/$B$3*100 | O27: 2017 | P27: =LOOKUP(DATE($O27,P$24,P$23),$A$2:$A$2941,$H$2:$H$2941) | Q27: =LOOKUP(DATE($O27,Q$24,Q$23),$A$2:$A$2941,$H$2:$H$2941) | R27: =LOOKUP(DATE($O27,R$24,R$23),$A$2:$A$2941,$H$2:$H$2941) | S27: =LOOKUP(DATE($O27,S$24,S$23),$A$2:$A$2941,$H$2:$H$2941) | T27: =LOOKUP(DATE($O27,T$24,T$23),$A$2:$A$2941,$H$2:$H$2941) | U27: =LOOKUP(DATE($O27,U$24,U$23),$A$2:$A$2941,$H$2:$H$2941) | V27: =LOOKUP(DATE($O27,V$24,V$23),$A$2:$A$2941,$H$2:$H$2941) | W27: =LOOKUP(DATE($O27,W$24,W$23),$A$2:$A$2941,$H$2:$H$2941) | ... AA27: =LOOKUP(DATE($O27,AA$24,AA$23),$A$2:$A$2941,$H$2:$H$2941) | AD27: 2016 | AR27: (*) | AW27: Rentabilidad | AX27: Mensual | AY27: Trimestral | AZ27: Semestral | BA27: Anual | BB27: Acum. 2025
A28: 39478 | B28: 12223.14 | C28: =(B28/B27-1)/(A28-A27)*30 | D28: =B28/$B$3*100 | O28: 2018 | P28: =LOOKUP(DATE($O28,P$24,P$23),$A$2:$A$2941,$H$2:$H$2941) | Q28: =LOOKUP(DATE($O28,Q$24,Q$23),$A$2:$A$2941,$H$2:$H$2941) | R28: =LOOKUP(DATE($O28,R$24,R$23),$A$2:$A$2941,$H$2:$H$2941) | S28: =LOOKUP(DATE($O28,S$24,S$23),$A$2:$A$2941,$H$2:$H$2941) | T28: =LOOKUP(DATE($O28,T$24,T$23),$A$2:$A$2941,$H$2:$H$2941) | V28: =LOOKUP(DATE($O28,V$24,V$23),$A$2:$A$2941,$I$2:$I$2941) | W28: =LOOKUP(DATE($O28,W$24,W$23),$A$2:$A$2941,$I$2:$I$2941) | X28: =LOOKUP(DATE($O28,X$24,X$23),$A$2:$A$2941,$I$2:$I$2941) | Y28: =LOOKUP(DATE($O28,Y$24,Y$23),$A$2:$A$2941,$I$2:$I$2941) | Z28: =LOOKUP(DATE($O28,Z$24,Z$23),$A$2:$A$2941,$I$2:$I$2941) | AA28: =LOOKUP(DATE($O28,AA$24,AA$23),$A$2:$A$2941,$I$2:$I$2941) | AD28: 2017 | AW28: ICP (Bechmark) | AX28: =($AW20/AX20-1)/(AW19-AX19)*30 | AY28: =$AW20/AY20-1 | AZ28: =$AW20/AZ20-1 | BA28: =$AW20/BA20-1 | BB28: =+AQ82
A29: 39507 | B29: 12284.88 | C29: =(B29/B28-1)/(A29-A28)*30 | D29: =B29/$B$3*100 | O29: 2019 | P29: =LOOKUP(DATE($O29,P$24,P$23),$A$2:$A$2941,$I$2:$I$2941) | Q29: =LOOKUP(DATE($O29,Q$24,Q$23),$A$2:$A$2941,$I$2:$I$2941) | R29: =LOOKUP(DATE($O29,R$24,R$23),$A$2:$A$2941,$I$2:$I$2941) | S29: =LOOKUP(DATE($O29,S$24,S$23),$A$2:$A$2941,$I$2:$I$2941) | T29: =LOOKUP(DATE($O29,T$24,T$23),$A$2:$A$2941,$I$2:$I$2941) | U29: =LOOKUP(DATE($O29,U$24,U$23),$A$2:$A$2941,$I$2:$I$2941) | V29: =LOOKUP(DATE($O29,V$24,V$23),$A$2:$A$2941,$I$2:$I$2941) | W29: =LOOKUP(DATE($O29,W$24,W$23),$A$2:$A$2941,$I$2:$I$2941) | ... AA29: =LOOKUP(DATE($O29,AA$24,AA$23),$A$2:$A$2941,$I$2:$I$2941) | AD29: 2018 | AK29: =+V28 | AL29: =+W28 | AM29: =+X28 | AN29: =+Y28 | AO29: =+Z28 | AP29: =+AA28 | AQ29: =+H159/H153-1 | AW29: Competencia | AX29: =($AW21/AX21-1)/(AW19-AX19)*30 | AY29: =($AW21)/AY21-1 | AZ29: =($AW21)/AZ21-1 | BA29: =($AW21)/BA21-1 | BB29: =+AQ83
A30: 39538 | B30: 12351.45 | C30: =(B30/B29-1)/(A30-A29)*30 | D30: =B30/$B$3*100 | O30: 2020 | P30: =LOOKUP(DATE($O30,P$24,P$23),$A$2:$A$2941,$I$2:$I$2941) | Q30: =LOOKUP(DATE($O30,Q$24,Q$23)+1,$A$2:$A$2941,$I$2:$I$2941) | R30: =LOOKUP(DATE($O30,R$24,R$23),$A:$A,$I:$I) | S30: =LOOKUP(DATE($O30,S$24,S$23),$A:$A,$I:$I) | T30: =LOOKUP(DATE($O30,T$24,T$23),$A:$A,$I:$I) | U30: =LOOKUP(DATE($O30,U$24,U$23),$A:$A,$I:$I) | V30: =LOOKUP(DATE($O30,V$24,V$23),$A:$A,$I:$I) | W30: =LOOKUP(DATE($O30,W$24,W$23),$A:$A,$I:$I) | X30: =LOOKUP(DATE($O30,X$24,X$23),$A:$A,$I:$I) | Y30: =+I181 | Z30: =+I182 | AA30: =+I183 | AD30: 2019 | AE30: =+P29 | AF30: =+Q29 | AG30: =+R29 | AH30: =+S29 | AI30: =+T29 | AJ30: =+U29 | AK30: =+V29 | AL30: =+W29 | ... AP30: =+AA29 | AQ30: =+(H171/H159-1)/COUNTA(AE30:AP30)*12 | AW30: FIP Monetario | AX30: =($AW22/AX22-1)/(AW19-AX19)*30 | AY30: =+AW22/AY22-1 | AZ30: =+AW22/AZ22-1 | BA30: =($AW22)/BA22-1 | BB30: =+AQ84
A31: 39568 | B31: 12416.18 | C31: =(B31/B30-1)/(A31-A30)*30 | D31: =B31/$B$3*100 | O31: 2021 | P31: =+I184 | Q31: =+I185 | R31: =+I186 | S31: =+I187 | T31: =+I188 | U31: =+I189 | V31: =+I190 | W31: =+I191 | X31: =+I192 | Y31: =+I193 | Z31: =+I194 | AA31: =+I195 | AD31: 2020 | AE31: =+P30 | AF31: =+Q30 | AG31: =+R30 | AH31: =+S30 | AI31: =+T30 | AJ31: =+U30 | AK31: =+V30 | AL31: =+W30 | ... AP31: =+AA30 | AQ31: =+(H180/H171-1)/COUNTA(AE31:AP31)*12
A32: 39598 | B32: 12481.48 | C32: =(B32/B31-1)/(A32-A31)*30 | D32: =B32/$B$3*100 | O32: 2022 | P32: =+I196 | Q32: =+I197 | R32: =+I198 | S32: =+I199 | T32: =+I200 | U32: =+I201 | V32: =+I202 | W32: =+I203 | X32: =+I204 | Y32: =+I205 | Z32: =+I206 | AA32: =+I207 | AD32: 2021 | AE32: =+P31 | AF32: =+Q31 | AG32: =+R31 | AH32: =+S31 | AI32: =+T31 | AJ32: =+U31 | AK32: =+V31 | AL32: =+W31 | ... AP32: =+AA31 | AQ32: =+(H195/H183-1)/COUNTA(AE32:AP32)*12
A33: 39629 | B33: 12552.23 | C33: =(B33/B32-1)/(A33-A32)*30 | D33: =B33/$B$3*100 | O33: 2023 | P33: =+I208 | Q33: =+I209 | R33: =+I210 | S33: =+I211 | T33: =+I212 | U33: =+I213 | V33: =+I214 | W33: =+I215 | X33: =+I216 | Y33: =+I217 | Z33: =+I218 | AA33: =+I219 | AD33: 2022 | AE33: =+P32 | AF33: =+Q32 | AG33: =+R32 | AH33: =+S32 | AI33: =+T32 | AJ33: =+U32 | AK33: =+V32 | AL33: =+W32 | ... AP33: =+AA32 | AQ33: =+(H207/H195-1)/COUNTA(AE33:AP33)*12
A34: 39660 | B34: 12628.9 | C34: =(B34/B33-1)/(A34-A33)*30 | D34: =B34/$B$3*100 | O34: 2024 | P34: =+I220 | Q34: =+I221 | R34: =+I222 | S34: =+I223 | T34: =+I224 | U34: =+I225 | V34: =+I226 | W34: =+I227 | X34: =+I228 | Y34: =+I229 | Z34: =+I230 | AA34: =+I231 | AD34: 2023 | AE34: =+P33 | AF34: =+Q33 | AG34: =+R33 | AH34: =+S33 | AI34: =+T33 | AJ34: =+U33 | AK34: =+V33 | AL34: =+W33 | ... AP34: =+AA33 | AQ34: =+(H219/H207-1)/COUNTA(AE34:AP34)*12
A35: 39689 | B35: 12704.63 | C35: =(B35/B34-1)/(A35-A34)*30 | D35: =B35/$B$3*100 | O35: 2025 | P35: =+I232 | AD35: 2024 | AE35: =+P34 | AF35: =+Q34 | AG35: =+R34 | AH35: =+S34 | AI35: =+T34 | AJ35: =+U34 | AK35: =+V34 | AL35: =+W34 | ... AP35: =+AA34 | AQ35: =+(H231/H219-1)/COUNTA(AE35:AP35)*12 | AR35: (*)
A36: 39721 | B36: 12796.95 | C36: =(B36/B35-1)/(A36-A35)*30 | D36: =B36/$B$3*100 | P36: 31 | Q36: 28 | R36: 31 | S36: 30 | T36: 31 | U36: 30 | V36: 31 | W36: 31 | X36: 30 | Y36: 31 | Z36: 30 | AA36: 31 | AD36: 2025 | AE36: =+P35 | AQ36: =+(H232/H231-1)/COUNTA(AE36:AP36)*12
A37: 39752 | B37: 12885.37 | C37: =(B37/B36-1)/(A37-A36)*30 | D37: =B37/$B$3*100 | P37: 1 | Q37: 2 | R37: 3 | S37: 4 | T37: 5 | U37: 6 | V37: 7 | W37: 8 | X37: 9 | Y37: 10 | Z37: 11 | AA37: 12 | AD37: (*) Acum a Mar | AR37: (*)
A38: 39780 | B38: 12970.93 | C38: =(B38/B37-1)/(A38-A37)*30 | D38: =B38/$B$3*100 | O38: Competencia | P38: Ene | Q38: Feb | R38: Mar | S38: Abr | T38: May | U38: Jun | V38: Jul | W38: Ago | X38: Sep | Y38: Oct | Z38: Nov | AA38: Dic | AD38: Competencia | AE38: Ene | AF38: Feb | AG38: Mar | AH38: Abr | AI38: May | AJ38: Jun | AK38: Jul | AL38: Ago | AM38: Sep | AN38: Oct | AO38: Nov | AP38: Dic | AQ38: Total Año
A39: 39813 | B39: 13066.33 | C39: =(B39/B38-1)/(A39-A38)*30 | D39: =B39/$B$3*100 | O39: 2016 | U39: =LOOKUP(DATE($O39,U$37,U$36),$A$2:$A$2941,$L$2:$L$2941) | V39: =LOOKUP(DATE($O39,V$37,V$36),$A$2:$A$2941,$L$2:$L$2941) | W39: =LOOKUP(DATE($O39,W$37,W$36),$A$2:$A$2941,$L$2:$L$2941) | X39: =LOOKUP(DATE($O39,X$37,X$36),$A$2:$A$2941,$L$2:$L$2941) | Y39: =LOOKUP(DATE($O39,Y$37,Y$36),$A$2:$A$2941,$L$2:$L$2941) | Z39: =LOOKUP(DATE($O39,Z$37,Z$36),$A$2:$A$2941,$L$2:$L$2941) | AA39: =LOOKUP(DATE($O39,AA$37,AA$36),$A$2:$A$2941,$L$2:$L$2941) | AD39: 2016 | AJ39: =+U39 | AK39: =+V39 | AL39: =+W39 | AM39: =+X39 | AN39: =+Y39 | AO39: =+Z39 | AP39: =+AA39 | AQ39: =+K136/K129-1
A40: 39843 | B40: 13151.16 | C40: =(B40/B39-1)/(A40-A39)*30 | D40: =B40/$B$3*100 | O40: 2017 | P40: =LOOKUP(DATE($O40,P$37,P$36),$A$2:$A$2941,$L$2:$L$2941) | Q40: =LOOKUP(DATE($O40,Q$37,Q$36),$A$2:$A$2941,$L$2:$L$2941) | R40: =LOOKUP(DATE($O40,R$37,R$36),$A$2:$A$2941,$L$2:$L$2941) | S40: =LOOKUP(DATE($O40,S$37,S$36),$A$2:$A$2941,$L$2:$L$2941) | T40: =LOOKUP(DATE($O40,T$37,T$36),$A$2:$A$2941,$L$2:$L$2941) | U40: =LOOKUP(DATE($O40,U$37,U$36),$A$2:$A$2941,$L$2:$L$2941) | V40: =LOOKUP(DATE($O40,V$37,V$36),$A$2:$A$2941,$L$2:$L$2941) | W40: =LOOKUP(DATE($O40,W$37,W$36),$A$2:$A$2941,$L$2:$L$2941) | ... AA40: =LOOKUP(DATE($O40,AA$37,AA$36),$A$2:$A$2941,$L$2:$L$2941) | AD40: 2017 | AE40: =+P40 | AF40: =+Q40 | AG40: =+R40 | AH40: =+S40 | AI40: =+T40 | AJ40: =+U40 | AK40: =+V40 | AL40: =+W40 | ... AP40: =+AA40 | AQ40: =+K147/K135-1
...

Sheet rentabilidad
S1: Rentabilidad | T1: Mensual | U1: Trimestral | V1: Semestral | W1: Anual | X1: Acum 2026 (*)
S2: ICP (Benchmark) | T2: 0.00375 | U2: 0.01129224 | V2: 0.023035476 | W2: 0.048206798 | X2: 0.018891153
S3: Competencia | T3: 0.0025969787 | U3: 0.0077498909 | V3: 0.016195359 | X3: 0.010495443
S4: FIP Monetario | T4: 0.0062980202 | U4: 0.01878682 | V4: 0.037933354 | X4: 0.026428459
C6: Año | D6: Fondo | E6: Ene | F6: Feb | G6: Mar | H6: Abr | I6: May | J6: Jun | K6: Jul | L6: Ago | M6: Sep | N6: Oct | O6: Nov | P6: Dic | Q6: Total Año
C8: 2013 | D8: ICP | E8: 0.0047208919 | F8: 0.0038962305 | G8: 0.0038950744 | H8: 0.0045881192 | I8: 0.0043264751 | J8: 0.0038974733 | K8: 0.0046128973 | L8: 0.0041770099 | M8: 0.0043152324 | N8: 0.004090765 | O8: 0.0039024428 | P8: 0.0038821497 | Q8: 0.051480393
C9: 2014 | D9: ICP | E9: 0.004004292 | F9: 0.0034323583 | G9: 0.003549793 | H9: 0.003337849 | I9: 0.0033374357 | J9: 0.0034491836 | K9: 0.003351129 | L9: 0.0029489802 | M9: 0.0029682413 | N9: 0.0026295969 | O9: 0.0024227109 | P9: 0.0026711642 | Q9: 0.038774076
C10: 2015 | D10: ICP | E10: 0.0025891255 | F10: 0.0023349759 | G10: 0.002671756 | H10: 0.0025049535 | I10: 0.0024184444 | J10: 0.0026691541 | K10: 0.0025846248 | L10: 0.0025839949 | M10: 0.0025057257 | N10: 0.0026027067 | O10: 0.0028025006 | P10: 0.0027922805 | Q10: 0.031506145
C11: 2016 | D11: ICP | E11: 0.0029214385 | F11: 0.0030180006 | G11: 0.0030183891 | H11: 0.0028228469 | I11: 0.0031161611 | J11: 0.0029205378 | K11: 0.0030178933 | L11: 0.0030181427 | M11: 0.0029247653 | N11: 0.0030136178 | O11: 0.0029201881 | P11: 0.0030401845 | Q11: 0.036343838
C12: 2017 | D12: ICP | E12: 0.0028965409 | F12: 0.0025015194 | G12: 0.002702122 | H12: 0.0022549129 | I12: 0.0024374684 | J12: 0.0020872576 | K12: 0.0021564911 | L12: 0.0021541098 | M12: 0.0020825098 | N12: 0.0021578523 | O12: 0.0020859581 | P12: 0.0009027616 | Q12: 0.016460814
C13: 2018 | D13: ICP | E13: 0.0034041239 | F13: 0.0019421991 | G13: 0.0021549289 | H13: 0.0020781004 | I13: 0.002140294 | J13: 0.0020877493 | K13: 0.0021543134 | L13: 0.0021454146 | M13: 0.002048507 | N13: 0.0022757308 | O13: 0.0022929957 | P13: 0.0023676656 | Q13: 0.027430166
D14: Competencia | E14: 0.0011515687 | F14: 0.0011138344 | G14: 0.001069593 | H14: 0.0010330782 | I14: 0.0010330782 | J14: 0.0010162455 | K14: 0.001015637 | L14: 0.0010184493 | M14: 0.0010093313 | N14: 0.0010753571 | O14: 0.0010253323 | P14: 0.0013472862 | Q14: 0.011953875
D15: FIP Monetario | K15: 0.0023909032 | L15: 0.0023104853 | M15: 0.0022586141 | N15: 0.0022551065 | O15: 0.0024405622 | P15: 0.0023909053 | Q15: 0.014444312
C16: 2019 | D16: ICP | E16: 0.0024509489 | F16: 0.0022528628 | G16: 0.0025833154 | H16: 0.0025004298 | I16: 0.0025858717 | J16: 0.0022209647 | K16: 0.0021468084 | L16: 0.0021550628 | M16: 0.0017218391 | N16: 0.0016715062 | O16: 0.0014213813 | P16: 0.0014832905 | Q16: 0.025486252
D17: Competencia | E17: 0.001321015 | F17: 0.0013955733 | G17: 0.0014022137 | H17: 0.0014166869 | I17: 0.0013232764 | J17: 0.0011990712 | K17: 0.001003694 | L17: 0.00093098055 | M17: 0.0010683168 | N17: 0.00062931784 | O17: 0.00069172632 | P17: 0.00060041282 | Q17: 0.013208386
D18: FIP Monetario | E18: 0.0022459142 | F18: 0.002308506 | G18: 0.0021889809 | H18: 0.0027459274 | I18: 0.002485931 | J18: 0.0026031201 | K18: 0.0020877763 | L18: 0.0018834714 | M18: 0.0017893238 | N18: 0.0013722478 | O18: 0.0015959327 | P18: 0.0019911043 | Q18: 0.025921581
C19: 2020 | D19: ICP | E19: 0.0016558085 | F19: 0.0013798586 | G19: 0.0011337054 | H19: 0.00045638918 | I19: 0.00045618099 | J19: 0.00045597298 | K19: 0.00045576517 | L19: 0 | M19: 0 | Q19: 0.011424214
D20: Competencia | E20: 0.00049404844 | F20: 0.00049289129 | G20: 0.00091798262 | H20: 0.0022000866 | I20: 0.00031021087 | J20: 0.0001001083 | K20: 9.1009797e-05 | L20: 9.4275942e-05 | M20: 7.0870692e-05 | Q20: 0.0064360987
D21: FIP Monetario | E21: 0.0013464361 | F21: 0.0012495922 | G21: 0.0011464172 | H21: 0.001023851 | I21: 0.00061178334 | J21: 0.00056555055 | K21: 0.00040031205 | L21: 0.00052367364 | M21: 0.00054322224 | N21: 0.0007 | O21: 0.0007 | P21: 0.0003 | Q21: 0.010037342
C22: 2021 | D22: ICP | E22: =+'Datos ICP (2)'!AE70 | F22: =+'Datos ICP (2)'!AF70 | G22: =+'Datos ICP (2)'!AG70 | H22: =+'Datos ICP (2)'!AH70 | I22: =+'Datos ICP (2)'!AI70 | J22: =+'Datos ICP (2)'!AJ70 | K22: =+'Datos ICP (2)'!AK70 | L22: =+'Datos ICP (2)'!AL70 | ... Q22: =+'Datos ICP (2)'!AQ70
D23: Competencia | E23: =+'Datos ICP (2)'!AE71 | F23: =+'Datos ICP (2)'!AF71 | G23: =+'Datos ICP (2)'!AG71 | H23: =+'Datos ICP (2)'!AH71 | I23: =+'Datos ICP (2)'!AI71 | J23: =+'Datos ICP (2)'!AJ71 | K23: =+'Datos ICP (2)'!AK71 | L23: =+'Datos ICP (2)'!AL71 | ... Q23: =+'Datos ICP (2)'!AQ71
D24: FIP Monetario | E24: =+'Datos ICP (2)'!AE72 | F24: =+'Datos ICP (2)'!AF72 | G24: =+'Datos ICP (2)'!AG72 | H24: =+'Datos ICP (2)'!AH72 | I24: =+'Datos ICP (2)'!AI72 | J24: =+'Datos ICP (2)'!AJ72 | K24: =+'Datos ICP (2)'!AK72 | L24: =+'Datos ICP (2)'!AL72 | ... Q24: =+'Datos ICP (2)'!AQ72
C25: 2022 | D25: ICP | E25: =+'Datos ICP (2)'!AE73 | F25: =+'Datos ICP (2)'!AF73 | G25: =+'Datos ICP (2)'!AG73 | H25: =+'Datos ICP (2)'!AH73 | I25: =+'Datos ICP (2)'!AI73 | J25: =+'Datos ICP (2)'!AJ73 | K25: =+'Datos ICP (2)'!AK73 | L25: =+'Datos ICP (2)'!AL73 | ... Q25: =+'Datos ICP (2)'!AQ73
D26: Competencia | E26: =+'Datos ICP (2)'!AE74 | F26: =+'Datos ICP (2)'!AF74 | G26: =+'Datos ICP (2)'!AG74 | H26: =+'Datos ICP (2)'!AH74 | I26: =+'Datos ICP (2)'!AI74 | J26: =+'Datos ICP (2)'!AJ74 | K26: =+'Datos ICP (2)'!AK74 | L26: =+'Datos ICP (2)'!AL74 | ... Q26: =+'Datos ICP (2)'!AQ74
D27: FIP Monetario | E27: =+'Datos ICP (2)'!AE75 | F27: =+'Datos ICP (2)'!AF75 | G27: =+'Datos ICP (2)'!AG75 | H27: =+'Datos ICP (2)'!AH75 | I27: =+'Datos ICP (2)'!AI75 | J27: =+'Datos ICP (2)'!AJ75 | K27: =+'Datos ICP (2)'!AK75 | L27: =+'Datos ICP (2)'!AL75 | ... Q27: =+'Datos ICP (2)'!AQ75
C28: 2023 | D28: ICP | E28: =+'Datos ICP (2)'!AE76 | F28: =+'Datos ICP (2)'!AF76 | G28: =+'Datos ICP (2)'!AG76 | H28: =+'Datos ICP (2)'!AH76 | I28: =+'Datos ICP (2)'!AI76 | J28: =+'Datos ICP (2)'!AJ76 | K28: =+'Datos ICP (2)'!AK76 | L28: =+'Datos ICP (2)'!AL76 | ... Q28: =+'Datos ICP (2)'!AQ76
D29: Competencia | E29: =+'Datos ICP (2)'!AE77 | F29: =+'Datos ICP (2)'!AF77 | G29: =+'Datos ICP (2)'!AG77 | H29: =+'Datos ICP (2)'!AH77 | I29: =+'Datos ICP (2)'!AI77 | J29: =+'Datos ICP (2)'!AJ77 | K29: =+'Datos ICP (2)'!AK77 | L29: =+'Datos ICP (2)'!AL77 | ... Q29: =+'Datos ICP (2)'!AQ77
D30: FIP Monetario | E30: =+'Datos ICP (2)'!AE78 | F30: =+'Datos ICP (2)'!AF78 | G30: =+'Datos ICP (2)'!AG78 | H30: =+'Datos ICP (2)'!AH78 | I30: =+'Datos ICP (2)'!AI78 | J30: =+'Datos ICP (2)'!AJ78 | K30: =+'Datos ICP (2)'!AK78 | L30: =+'Datos ICP (2)'!AL78 | ... Q30: =+'Datos ICP (2)'!AQ78
C31: 2024 | D31: ICP | E31: =+'Datos ICP (2)'!AE79 | F31: =+'Datos ICP (2)'!AF79 | G31: =+'Datos ICP (2)'!AG79 | H31: =+'Datos ICP (2)'!AH79 | I31: =+'Datos ICP (2)'!AI79 | J31: =+'Datos ICP (2)'!AJ79 | K31: =+'Datos ICP (2)'!AK79 | L31: =+'Datos ICP (2)'!AL79 | ... Q31: =+'Datos ICP (2)'!AQ79
D32: Competencia | E32: =+'Datos ICP (2)'!AE80 | F32: =+'Datos ICP (2)'!AF80 | G32: =+'Datos ICP (2)'!AG80 | H32: =+'Datos ICP (2)'!AH80 | I32: =+'Datos ICP (2)'!AI80 | J32: =+'Datos ICP (2)'!AJ80 | K32: =+'Datos ICP (2)'!AK80 | L32: =+'Datos ICP (2)'!AL80 | ... Q32: =+'Datos ICP (2)'!AQ80
D33: FIP Monetario | E33: =+'Datos ICP (2)'!AE81 | F33: =+'Datos ICP (2)'!AF81 | G33: =+'Datos ICP (2)'!AG81 | H33: =+'Datos ICP (2)'!AH81 | I33: =+'Datos ICP (2)'!AI81 | J33: =+'Datos ICP (2)'!AJ81 | K33: =+'Datos ICP (2)'!AK81 | L33: =+'Datos ICP (2)'!AL81 | ... Q33: =+'Datos ICP (2)'!AQ81
C34: 2025 | D34: ICP | E34: 0.0041666667 | F34: 0.0041666667 | G34: 0.0041666667 | H34: 0.0041666667 | I34: 0.0041666667 | J34: 0.0041666667 | K34: 0.0041477273 | L34: 0.0039583333 | M34: 0.0039583333 | N34: 0.0039583333 | O34: 0.0039583333 | P34: 0.003859127 | Q34: 0.049948367
D35: Competencia | E35: -0.11277665 | F35: 0.0027621377 | G35: 0.0030628269 | H35: 0.0029759497 | I35: 0.0030897625 | J35: 0.0029970525 | K35: 0.0029505495 | L35: 0.0030005422 | M35: 0.002761615 | N35: 0.0028651947 | O35: 0.0027950158 | P35: 0.0028377665 | Q35: -0.083879086
D36: FIP Monetario | L36: 0.0064265102 | M36: 0.0061120591 | N36: 0.006229496 | O36: 0.0061122752 | P36: 0.0060625621 | Q36: 0.031328222

Sheet composición
J1: Duración | N1: Instrumentos | R1: Moneda
O2: Bono | P2: 0
K3: Menos de 1 mes | L3: 1 | O3: Depósitos | P3: 0 | S3: Pesos | T3: 0.98267686
K4: 1-3 meses | L4: 0 | O4: Factoring | P4: 0 | S4: UF | T4: 0.017323136
K5: 3-4 meses | L5: 0 | O5: Financiamiento Inmobiliario | P5: 0.013080308
K6: Más de 4 meses | L6: 0 | O6: Financiamiento Mesa Moneda Extranjera | P6: 0.98691969
O7: Garantías | P7: 0
O8: Nota Estructurada | P8: 0
O9: Financiamiento Mesa Renta Fija | P9: 0
O10: Simultánea | P10: 0
O11: Efectos de Comercio | P11: 0
O13: Pagaré | P13: 0
A14: Facturas | B14: 0
P15: =SUM(P2:P13)
