Workbook
Name OLE_LINK1: 'Datos ICP (2)'!#REF!

Sheet Comentario
A2: El IPC de abril en Estados Unidos sorprendió levemente al alza respecto de las expectativas, impulsado principalmente por el fuerte aumento de los precios de la energía. La gasolina explicó una parte importante del avance del índice general, mientras que la inflación subyacente también mostró resiliencia, explicada en parte por un ajuste en los precios de arriendos tras las distorsiones asociadas al cierre parcial del gobierno el año pasado. El IPC general registró un aumento de 0,6% mensual, llevando la inflación anual a 3,8%, su mayor nivel en tres años. Por su parte, la inflación subyacente avanzó 0,4% mensual, impulsada por mayores costos de vivienda, particularmente en el componente equivalente de arriendo y arriendos efectivos. Por su parte, las nóminas no agrícolas aumentaron en 115 mil puestos durante abril, mientras que la tasa de desempleo se mantuvo estable en 4,3%, evidenciando un mercado laboral aún sólido. Por su parte, la Reserva Federal mantuvo una postura cautelosa respecto de la política monetaria, monitoreando tanto la persistencia de la inflación subyacente como los riesgos derivados del conflicto geopolítico y su impacto sobre los precios de la energía.

Sheet Datos ICP (2)
A1: CLICP Index | F1: Cuota LIQUIDEZ RESERVA DÓLAR | AD1: ICP | AE1: Ene | AF1: Feb | AG1: Mar | AH1: Abr | AI1: May | AJ1: Jun | AK1: Jul | AL1: Ago | AM1: Sep | AN1: Oct | AO1: Nov | AP1: Dic | AQ1: Total Año
A2: Fecha | B2: ICP | D2: ICP Norm. | J2: FondoLiquidez Reserva Dólar | K2: 8248-1 | M2: Competencia (*) | P2: Ene | Q2: Feb | R2: Mar | S2: Abr | T2: May | U2: Jun | V2: Jul | W2: Ago | X2: Sep | Y2: Oct | Z2: Nov | AA2: Dic | AD2: 2006 | AE2: =+P3 | AF2: =+Q3 | AG2: =+R3 | AH2: =+S3 | AI2: =+T3 | AJ2: =+U3 | AK2: =+V3 | AL2: =+W3 | ... AP2: =+AA3 | AQ2: =+B16/B3-1
A3: 38717 | B3: 10953.14 | D3: =B3/$B$3*100 | N3: =B3 | O3: 2006 | P3: =LOOKUP(DATE($O3,P$25,P$24),$A$2:$A$2943,$C$2:$C$2943) | Q3: =LOOKUP(DATE($O3,Q$25,Q$24),$A$2:$A$2943,$C$2:$C$2943) | R3: =LOOKUP(DATE($O3,R$25,R$24),$A$2:$A$2943,$C$2:$C$2943) | S3: =LOOKUP(DATE($O3,S$25,S$24),$A$2:$A$2943,$C$2:$C$2943) | T3: =LOOKUP(DATE($O3,T$25,T$24),$A$2:$A$2943,$C$2:$C$2943) | U3: =LOOKUP(DATE($O3,U$25,U$24),$A$2:$A$2943,$C$2:$C$2943) | V3: =LOOKUP(DATE($O3,V$25,V$24),$A$2:$A$2943,$C$2:$C$2943) | W3: =LOOKUP(DATE($O3,W$25,W$24),$A$2:$A$2943,$C$2:$C$2943) | ... AA3: =LOOKUP(DATE($O3,AA$25,AA$24),$A$2:$A$2943,$C$2:$C$2943) | AD3: 2007 | AE3: =+P4 | AF3: =+Q4 | AG3: =+R4 | AH3: =+S4 | AI3: =+T4 | AJ3: =+U4 | AK3: =+V4 | AL3: =+W4 | ... AP3: =+AA4 | AQ3: =+B28/B15-1
A4: 38748 | B4: 10996.85 | C4: =(B4/B3-1)/(A4-A3)*360 | D4: =B4/$B$3*100 | K4: Corporate Dollar Serie A Banchile | O4: 2007 | P4: =LOOKUP(DATE($O4,P$25,P$24),$A$2:$A$2943,$C$2:$C$2943) | Q4: =LOOKUP(DATE($O4,Q$25,Q$24),$A$2:$A$2943,$C$2:$C$2943) | R4: =LOOKUP(DATE($O4,R$25,R$24),$A$2:$A$2943,$C$2:$C$2943) | S4: =LOOKUP(DATE($O4,S$25,S$24),$A$2:$A$2943,$C$2:$C$2943) | T4: =LOOKUP(DATE($O4,T$25,T$24),$A$2:$A$2943,$C$2:$C$2943) | U4: =LOOKUP(DATE($O4,U$25,U$24),$A$2:$A$2943,$C$2:$C$2943) | V4: =LOOKUP(DATE($O4,V$25,V$24),$A$2:$A$2943,$C$2:$C$2943) | W4: =LOOKUP(DATE($O4,W$25,W$24),$A$2:$A$2943,$C$2:$C$2943) | ... AA4: =LOOKUP(DATE($O4,AA$25,AA$24),$A$2:$A$2943,$C$2:$C$2943) | AD4: 2008 | AE4: =+P5 | AF4: =+Q5 | AG4: =+R5 | AH4: =+S5 | AI4: =+T5 | AJ4: =+U5 | AK4: =+V5 | AL4: =+W5 | ... AP4: =+AA5 | AQ4: =+B41/B29-1
A5: 38776 | B5: 11035.11 | C5: =(B5/B4-1)/(A5-A4)*360 | D5: =B5/$B$3*100 | O5: 2008 | P5: =LOOKUP(DATE($O5,P$25,P$24),$A$2:$A$2943,$C$2:$C$2943) | Q5: =LOOKUP(DATE($O5,Q$25,Q$24),$A$2:$A$2943,$C$2:$C$2943) | R5: =LOOKUP(DATE($O5,R$25,R$24),$A$2:$A$2943,$C$2:$C$2943) | S5: =LOOKUP(DATE($O5,S$25,S$24),$A$2:$A$2943,$C$2:$C$2943) | T5: =LOOKUP(DATE($O5,T$25,T$24),$A$2:$A$2943,$C$2:$C$2943) | U5: =LOOKUP(DATE($O5,U$25,U$24),$A$2:$A$2943,$C$2:$C$2943) | V5: =LOOKUP(DATE($O5,V$25,V$24),$A$2:$A$2943,$C$2:$C$2943) | W5: =LOOKUP(DATE($O5,W$25,W$24),$A$2:$A$2943,$C$2:$C$2943) | ... AA5: =LOOKUP(DATE($O5,AA$25,AA$24),$A$2:$A$2943,$C$2:$C$2943) | AD5: 2009 | AE5: =+P6 | AF5: =+Q6 | AG5: =+R6 | AH5: =+S6 | AI5: =+T6 | AJ5: =+U6 | AK5: =+V6 | AL5: =+W6 | ... AP5: =+AA6 | AQ5: =+B53/B41-1
A6: 38807 | B6: 11078.66 | C6: =(B6/B5-1)/(A6-A5)*360 | D6: =B6/$B$3*100 | O6: 2009 | P6: =LOOKUP(DATE($O6,P$25,P$24),$A$2:$A$2943,$C$2:$C$2943) | Q6: =LOOKUP(DATE($O6,Q$25,Q$24),$A$2:$A$2943,$C$2:$C$2943) | R6: =LOOKUP(DATE($O6,R$25,R$24),$A$2:$A$2943,$C$2:$C$2943) | S6: =LOOKUP(DATE($O6,S$25,S$24),$A$2:$A$2943,$C$2:$C$2943) | T6: =LOOKUP(DATE($O6,T$25,T$24),$A$2:$A$2943,$C$2:$C$2943) | U6: =LOOKUP(DATE($O6,U$25,U$24),$A$2:$A$2943,$C$2:$C$2943) | V6: =LOOKUP(DATE($O6,V$25,V$24),$A$2:$A$2943,$C$2:$C$2943) | W6: =LOOKUP(DATE($O6,W$25,W$24),$A$2:$A$2943,$C$2:$C$2943) | ... AA6: =LOOKUP(DATE($O6,AA$25,AA$24),$A$2:$A$2943,$C$2:$C$2943) | AD6: 2010 | AE6: =+P7 | AF6: =+Q7 | AG6: =+R7 | AH6: =+S7 | AI6: =+T7 | AJ6: =+U7 | AK6: =+V7 | AL6: =+W7 | ... AP6: =+AA7 | AQ6: =+B65/B53-1
A7: 38835 | B7: 11118.82 | C7: =(B7/B6-1)/(A7-A6)*360 | D7: =B7/$B$3*100 | O7: 2010 | P7: =LOOKUP(DATE($O7,P$25,P$24),$A$2:$A$2943,$C$2:$C$2943) | Q7: =LOOKUP(DATE($O7,Q$25,Q$24),$A$2:$A$2943,$C$2:$C$2943) | R7: =LOOKUP(DATE($O7,R$25,R$24),$A$2:$A$2943,$C$2:$C$2943) | S7: =LOOKUP(DATE($O7,S$25,S$24),$A$2:$A$2943,$C$2:$C$2943) | T7: =LOOKUP(DATE($O7,T$25,T$24),$A$2:$A$2943,$C$2:$C$2943) | U7: =LOOKUP(DATE($O7,U$25,U$24),$A$2:$A$2943,$C$2:$C$2943) | V7: =LOOKUP(DATE($O7,V$25,V$24),$A$2:$A$2943,$C$2:$C$2943) | W7: =LOOKUP(DATE($O7,W$25,W$24),$A$2:$A$2943,$C$2:$C$2943) | ... AA7: =LOOKUP(DATE($O7,AA$25,AA$24),$A$2:$A$2943,$C$2:$C$2943) | AD7: 2011 | AE7: =+P8 | AF7: =+Q8 | AG7: =+R8 | AH7: =+S8 | AI7: =+T8 | AJ7: =+U8 | AK7: =+V8 | AL7: =+W8 | ... AP7: =+AA8 | AQ7: =+B77/B65-1
A8: 38868 | B8: 11169.1 | C8: =(B8/B7-1)/(A8-A7)*360 | D8: =B8/$B$3*100 | O8: 2011 | P8: =LOOKUP(DATE($O8,P$25,P$24),$A$2:$A$2943,$C$2:$C$2943) | Q8: =LOOKUP(DATE($O8,Q$25,Q$24),$A$2:$A$2943,$C$2:$C$2943) | R8: =LOOKUP(DATE($O8,R$25,R$24),$A$2:$A$2943,$C$2:$C$2943) | S8: =LOOKUP(DATE($O8,S$25,S$24),$A$2:$A$2943,$C$2:$C$2943) | T8: =LOOKUP(DATE($O8,T$25,T$24),$A$2:$A$2943,$C$2:$C$2943) | U8: =LOOKUP(DATE($O8,U$25,U$24),$A$2:$A$2943,$C$2:$C$2943) | V8: =LOOKUP(DATE($O8,V$25,V$24),$A$2:$A$2943,$C$2:$C$2943) | W8: =LOOKUP(DATE($O8,W$25,W$24),$A$2:$A$2943,$C$2:$C$2943) | ... AA8: =LOOKUP(DATE($O8,AA$25,AA$24),$A$2:$A$2943,$C$2:$C$2943) | AD8: 2012 | AE8: =+P9 | AF8: =+Q9 | AG8: =+R9 | AH8: =+S9 | AI8: =+T9 | AJ8: =+U9 | AK8: =+V9 | AL8: =+W9 | ... AP8: =+AA9 | AQ8: =+B89/B78-1
A9: 38898 | B9: 11215.04 | C9: =(B9/B8-1)/(A9-A8)*360 | D9: =B9/$B$3*100 | O9: 2012 | P9: =LOOKUP(DATE($O9,P$25,P$24),$A$2:$A$2943,$C$2:$C$2943) | Q9: =LOOKUP(DATE($O9,Q$25,Q$24),$A$2:$A$2943,$C$2:$C$2943) | R9: =LOOKUP(DATE($O9,R$25,R$24),$A$2:$A$2943,$C$2:$C$2943) | S9: =LOOKUP(DATE($O9,S$25,S$24),$A$2:$A$2943,$C$2:$C$2943) | T9: =LOOKUP(DATE($O9,T$25,T$24),$A$2:$A$2943,$C$2:$C$2943) | U9: =LOOKUP(DATE($O9,U$25,U$24),$A$2:$A$2943,$C$2:$C$2943) | V9: =LOOKUP(DATE($O9,V$25,V$24),$A$2:$A$2943,$C$2:$C$2943) | W9: =LOOKUP(DATE($O9,W$25,W$24),$A$2:$A$2943,$C$2:$C$2943) | ... AA9: =LOOKUP(DATE($O9,AA$25,AA$24),$A$2:$A$2943,$C$2:$C$2943) | AD9: 2013 | AE9: =+P10 | AF9: =+Q10 | AG9: =+R10 | AH9: =+S10 | AI9: =+T10 | AJ9: =+U10 | AK9: =+V10 | AL9: =+W10 | ... AP9: =+AA10 | AQ9: =+B101/B89-1
A10: 38929 | B10: 11263.22 | C10: =(B10/B9-1)/(A10-A9)*360 | D10: =B10/$B$3*100 | O10: 2013 | P10: =LOOKUP(DATE($O10,P$25,P$24),$A$2:$A$2943,$C$2:$C$2943) | Q10: =LOOKUP(DATE($O10,Q$25,Q$24),$A$2:$A$2943,$C$2:$C$2943) | R10: =LOOKUP(DATE($O10,R$25,R$24),$A$2:$A$2943,$C$2:$C$2943) | S10: =LOOKUP(DATE($O10,S$25,S$24),$A$2:$A$2943,$C$2:$C$2943) | T10: =LOOKUP(DATE($O10,T$25,T$24),$A$2:$A$2943,$C$2:$C$2943) | U10: =LOOKUP(DATE($O10,U$25,U$24),$A$2:$A$2943,$C$2:$C$2943) | V10: =LOOKUP(DATE($O10,V$25,V$24),$A$2:$A$2943,$C$2:$C$2943) | W10: =LOOKUP(DATE($O10,W$25,W$24),$A$2:$A$2943,$C$2:$C$2943) | ... AA10: =LOOKUP(DATE($O10,AA$25,AA$24),$A$2:$A$2943,$C$2:$C$2943) | AD10: 2014 | AE10: =+P11 | AF10: =+Q11 | AG10: =+R11 | AH10: =+S11 | AI10: =+T11 | AJ10: =+U11 | AK10: =+V11 | AL10: =+W11 | ... AP10: =+AA11 | AQ10: =+B113/B102-1
A11: 38960 | B11: 11313.29 | C11: =(B11/B10-1)/(A11-A10)*360 | D11: =B11/$B$3*100 | O11: 2014 | P11: =LOOKUP(DATE($O11,P$25,P$24),$A$2:$A$2943,$C$2:$C$2943) | Q11: =LOOKUP(DATE($O11,Q$25,Q$24),$A$2:$A$2943,$C$2:$C$2943) | R11: =LOOKUP(DATE($O11,R$25,R$24),$A$2:$A$2943,$C$2:$C$2943) | S11: =LOOKUP(DATE($O11,S$25,S$24),$A$2:$A$2943,$C$2:$C$2943) | T11: =LOOKUP(DATE($O11,T$25,T$24),$A$2:$A$2943,$C$2:$C$2943) | U11: =LOOKUP(DATE($O11,U$25,U$24),$A$2:$A$2943,$C$2:$C$2943) | V11: =LOOKUP(DATE($O11,V$25,V$24),$A$2:$A$2943,$C$2:$C$2943) | W11: =LOOKUP(DATE($O11,W$25,W$24),$A$2:$A$2943,$C$2:$C$2943) | ... AA11: =LOOKUP(DATE($O11,AA$25,AA$24),$A$2:$A$2943,$C$2:$C$2943) | AD11: 2015 | AE11: =+P12 | AF11: =+Q12 | AG11: =+R12 | AH11: =+S12 | AI11: =+T12 | AJ11: =+U12 | AK11: =+V12 | AL11: =+W12 | ... AP11: =+AA12 | AQ11: =+B125/B113-1
A12: 38989 | B12: 11360.92 | C12: =(B12/B11-1)/(A12-A11)*360 | D12: =B12/$B$3*100 | O12: 2015 | P12: =LOOKUP(DATE($O12,P$25,P$24),$A$2:$A$2943,$C$2:$C$2943) | Q12: =LOOKUP(DATE($O12,Q$25,Q$24),$A$2:$A$2943,$C$2:$C$2943) | R12: =LOOKUP(DATE($O12,R$25,R$24),$A$2:$A$2943,$C$2:$C$2943) | S12: =LOOKUP(DATE($O12,S$25,S$24),$A$2:$A$2943,$C$2:$C$2943) | T12: =LOOKUP(DATE($O12,T$25,T$24),$A$2:$A$2943,$C$2:$C$2943) | U12: =LOOKUP(DATE($O12,U$25,U$24),$A$2:$A$2943,$C$2:$C$2943) | V12: =LOOKUP(DATE($O12,V$25,V$24),$A$2:$A$2943,$C$2:$C$2943) | W12: =LOOKUP(DATE($O12,W$25,W$24),$A$2:$A$2943,$C$2:$C$2943) | ... AA12: =LOOKUP(DATE($O12,AA$25,AA$24),$A$2:$A$2943,$C$2:$C$2943) | AD12: 2016 | AE12: =+P13 | AF12: =+Q13 | AG12: =+R13 | AH12: =+S13 | AI12: =+T13 | AJ12: =+U13 | AK12: =+V13 | AL12: =+W13 | ... AP12: =+AA13 | AQ12: =+B137/B125-1
A13: 39021 | B13: 11413.02 | C13: =(B13/B12-1)/(A13-A12)*360 | D13: =B13/$B$3*100 | O13: 2016 | P13: =LOOKUP(DATE($O13,P$25,P$24),$A$2:$A$2943,$C$2:$C$2943) | Q13: =LOOKUP(DATE($O13,Q$25,Q$24),$A$2:$A$2943,$C$2:$C$2943) | R13: =LOOKUP(DATE($O13,R$25,R$24),$A$2:$A$2943,$C$2:$C$2943) | S13: =LOOKUP(DATE($O13,S$25,S$24),$A$2:$A$2943,$C$2:$C$2943) | T13: =LOOKUP(DATE($O13,T$25,T$24),$A$2:$A$2943,$C$2:$C$2943) | U13: =LOOKUP(DATE($O13,U$25,U$24),$A$2:$A$2943,$C$2:$C$2943) | V13: =LOOKUP(DATE($O13,V$25,V$24),$A$2:$A$2943,$C$2:$C$2943) | W13: =LOOKUP(DATE($O13,W$25,W$24),$A$2:$A$2943,$C$2:$C$2943) | ... AA13: =LOOKUP(DATE($O13,AA$25,AA$24),$A$2:$A$2943,$C$2:$C$2943) | AD13: 2017 | AE13: =+P14 | AF13: =+Q14 | AG13: =+R14 | AH13: =+S14 | AI13: =+T14 | AJ13: =+U14 | AK13: =+V14 | AL13: =+W14 | ... AP13: =+AA14 | AQ13: =+B149/B137-1
A14: 39051 | B14: 11463.01 | C14: =(B14/B13-1)/(A14-A13)*360 | D14: =B14/$B$3*100 | O14: 2017 | P14: =LOOKUP(DATE($O14,P$25,P$24),$A$2:$A$2943,$C$2:$C$2943) | Q14: =LOOKUP(DATE($O14,Q$25,Q$24),$A$2:$A$2943,$C$2:$C$2943) | R14: =LOOKUP(DATE($O14,R$25,R$24),$A$2:$A$2943,$C$2:$C$2943) | S14: =LOOKUP(DATE($O14,S$25,S$24),$A$2:$A$2943,$C$2:$C$2943) | T14: =LOOKUP(DATE($O14,T$25,T$24),$A$2:$A$2943,$C$2:$C$2943) | U14: =LOOKUP(DATE($O14,U$25,U$24),$A$2:$A$2943,$C$2:$C$2943) | V14: =LOOKUP(DATE($O14,V$25,V$24),$A$2:$A$2943,$C$2:$C$2943) | W14: =LOOKUP(DATE($O14,W$25,W$24),$A$2:$A$2943,$C$2:$C$2943) | ... AA14: =LOOKUP(DATE($O14,AA$25,AA$24),$A$2:$A$2943,$C$2:$C$2943) | AD14: 2018 | AE14: =+P15 | AF14: =+Q15 | AG14: =+R15 | AH14: =+S15 | AI14: =+T15 | AJ14: =+U15 | AK14: =+V15 | AL14: =+W15 | ... AP14: =+AA15 | AQ14: =+B161/B149-1
A15: 39080 | B15: 11512.49 | C15: =(B15/B14-1)/(A15-A14)*360 | D15: =B15/$B$3*100 | O15: 2018 | P15: =LOOKUP(DATE($O15,P$25,P$24),$A$2:$A$2943,$C$2:$C$2943) | Q15: =LOOKUP(DATE($O15,Q$25,Q$24),$A$2:$A$2943,$C$2:$C$2943) | R15: =LOOKUP(DATE($O15,R$25,R$24),$A$2:$A$2943,$C$2:$C$2943) | S15: =LOOKUP(DATE($O15,S$25,S$24),$A$2:$A$2943,$C$2:$C$2943) | T15: =LOOKUP(DATE($O15,T$25,T$24),$A$2:$A$2943,$C$2:$C$2943) | U15: =LOOKUP(DATE($O15,U$25,U$24),$A$2:$A$2943,$C$2:$C$2943) | V15: =LOOKUP(DATE($O15,V$25,V$24),$A$2:$A$2943,$C$2:$C$2943) | W15: =LOOKUP(DATE($O15,W$25,W$24),$A$2:$A$2943,$C$2:$C$2943) | ... AA15: =LOOKUP(DATE($O15,AA$25,AA$24),$A$2:$A$2943,$C$2:$C$2943) | AD15: 2019 | AE15: =+P16 | AF15: =+Q16 | AG15: =+R16 | AH15: =+S16 | AI15: =+T16 | AJ15: =+U16 | AK15: =+V16 | AL15: =+W16 | ... AP15: =+AA16 | AQ15: =+(B173/B161-1)/COUNTA(AE15:AP15)*12 | AR15: (*)
A16: 39113 | B16: 11567.23 | C16: =(B16/B15-1)/(A16-A15)*360 | D16: =B16/$B$3*100 | O16: 2019 | P16: =LOOKUP(DATE($O16,P$25,P$24),$A$2:$A$2943,$C$2:$C$2943) | Q16: =LOOKUP(DATE($O16,Q$25,Q$24),$A$2:$A$2943,$C$2:$C$2943) | R16: =LOOKUP(DATE($O16,R$25,R$24),$A$2:$A$2943,$C$2:$C$2943) | S16: =LOOKUP(DATE($O16,S$25,S$24),$A$2:$A$2943,$C$2:$C$2943) | T16: =LOOKUP(DATE($O16,T$25,T$24),$A$2:$A$2943,$C$2:$C$2943) | U16: =LOOKUP(DATE($O16,U$25,U$24),$A$2:$A$2943,$C$2:$C$2943) | V16: =LOOKUP(DATE($O16,V$25,V$24),$A$2:$A$2943,$C$2:$C$2943) | W16: =LOOKUP(DATE($O16,W$25,W$24),$A$2:$A$2943,$C$2:$C$2943) | ... AA16: =LOOKUP(DATE($O16,AA$25,AA$24),$A$2:$A$2943,$C$2:$C$2943) | AD16: 2020 | AE16: =+P17 | AF16: =+Q17 | AG16: =+R17 | AH16: =+S17 | AI16: =+T17 | AJ16: =+U17 | AK16: =+V17 | AL16: =+W17 | ... AP16: =+AA17 | AQ16: =+(B185/B173-1)/COUNTA(AE16:AP16)*12
A17: 39141 | B17: 11612.68 | C17: =(B17/B16-1)/(A17-A16)*360 | D17: =B17/$B$3*100 | O17: 2020 | P17: =LOOKUP(DATE($O17,P$25,P$24),$A$2:$A$2943,$C$2:$C$2943) | Q17: =LOOKUP(DATE($O17,Q$25,Q$24)+1,$A$2:$A$2943,$C$2:$C$2943) | R17: =LOOKUP(DATE($O17,R$25,R$24),$A$2:$A$2943,$C$2:$C$2943) | S17: =LOOKUP(DATE($O17,S$25,S$24),$A:$A,$C:$C) | T17: =LOOKUP(DATE($O17,T$25,T$24),$A:$A,$C:$C) | U17: =LOOKUP(DATE($O17,U$25,U$24),$A:$A,$C:$C) | V17: =LOOKUP(DATE($O17,V$25,V$24),$A:$A,$C:$C) | W17: =LOOKUP(DATE($O17,W$25,W$24),$A:$A,$C:$C) | X17: =LOOKUP(DATE($O17,X$25,X$24),$A:$A,$C:$C) | Y17: =LOOKUP(DATE($O17,Y$25,Y$24),$A:$A,$C:$C) | Z17: =LOOKUP(DATE($O17,Z$25,Z$24),$A:$A,$C:$C) | AA17: =LOOKUP(DATE($O17,AA$25,AA$24),$A:$A,$C:$C) | AD17: 2021 | AE17: =+P18 | AF17: =+Q18 | AG17: =+R18 | AH17: =+S18 | AI17: =+T18 | AJ17: =+U18 | AK17: =+V18 | AL17: =+W18 | ... AP17: =+AA18 | AQ17: =+(B197/B185-1)/COUNTA(AE17:AP17)*12
A18: 39171 | B18: 11661.5 | C18: =(B18/B17-1)/(A18-A17)*360 | D18: =B18/$B$3*100 | O18: 2021 | P18: =LOOKUP(DATE($O18,P$25,P$24),$A$2:$A$2943,$C$2:$C$2943) | Q18: =LOOKUP(DATE($O18,Q$25,Q$24)+1,$A$2:$A$2943,$C$2:$C$2943) | R18: =LOOKUP(DATE($O18,R$25,R$24),$A$2:$A$2943,$C$2:$C$2943) | S18: =LOOKUP(DATE($O18,S$25,S$24),$A:$A,$C:$C) | T18: =LOOKUP(DATE($O18,T$25,T$24),$A:$A,$C:$C) | U18: =LOOKUP(DATE($O18,U$25,U$24),$A:$A,$C:$C) | V18: =LOOKUP(DATE($O18,V$25,V$24),$A:$A,$C:$C) | W18: =LOOKUP(DATE($O18,W$25,W$24),$A:$A,$C:$C) | X18: =LOOKUP(DATE($O18,X$25,X$24),$A:$A,$C:$C) | Y18: =LOOKUP(DATE($O18,Y$25,Y$24),$A:$A,$C:$C) | Z18: =LOOKUP(DATE($O18,Z$25,Z$24),$A:$A,$C:$C) | AA18: =LOOKUP(DATE($O18,AA$25,AA$24),$A:$A,$C:$C) | AD18: 2022 | AE18: =+P19 | AF18: =+Q19 | AG18: =+R19 | AH18: =+S19 | AI18: =+T19 | AJ18: =+U19 | AK18: =+V19 | AL18: =+W19 | ... AP18: =+AA19 | AQ18: =+(B209/B197-1)/COUNTA(AE18:AP18)*12 | AX18: -1 | AY18: -3 | AZ18: -6 | BA18: -12
A19: 39202 | B19: 11712.58 | C19: =(B19/B18-1)/(A19-A18)*360 | D19: =B19/$B$3*100 | O19: 2022 | P19: =LOOKUP(DATE($O19,P$25,P$24),$A$2:$A$2943,$C$2:$C$2943) | Q19: =LOOKUP(DATE($O19,Q$25,Q$24),$A$2:$A$2943,$C$2:$C$2943) | R19: =LOOKUP(DATE($O19,R$25,R$24),$A$2:$A$2943,$C$2:$C$2943) | S19: =LOOKUP(DATE($O19,S$25,S$24),$A$2:$A$2943,$C$2:$C$2943) | T19: =LOOKUP(DATE($O19,T$25,T$24),$A$2:$A$2943,$C$2:$C$2943) | U19: =LOOKUP(DATE($O19,U$25,U$24),$A$2:$A$2943,$C$2:$C$2943) | V19: =LOOKUP(DATE($O19,V$25,V$24),$A$2:$A$2943,$C$2:$C$2943) | W19: =LOOKUP(DATE($O19,W$25,W$24),$A$2:$A$2943,$C$2:$C$2943) | ... AA19: =LOOKUP(DATE($O19,AA$25,AA$24),$A$2:$A$2943,$C$2:$C$2943) | AD19: 2023 | AE19: =+P20 | AF19: =+Q20 | AG19: =+R20 | AH19: =+S20 | AI19: =+T20 | AJ19: =+U20 | AK19: =+V20 | AL19: =+W20 | ... AP19: =+AA20 | AQ19: =+(B221/B209-1)/COUNTA(AE19:AP19)*12 | AV19: Ingresar mes actual==> | AW19: 46203 | AX19: =EOMONTH($AW19,AX18) | AY19: =EOMONTH($AW19,AY18) | AZ19: =EOMONTH($AW19,AZ18) | BA19: =EOMONTH($AW19,BA18) | BB19: 43100
A20: 39233 | B20: 11763.78 | C20: =(B20/B19-1)/(A20-A19)*360 | D20: =B20/$B$3*100 | O20: 2023 | P20: =LOOKUP(DATE($O20,P$25,P$24),$A$2:$A$2943,$C$2:$C$2943) | Q20: =LOOKUP(DATE($O20,Q$25,Q$24),$A$2:$A$2943,$C$2:$C$2943) | R20: =LOOKUP(DATE($O20,R$25,R$24),$A$2:$A$2943,$C$2:$C$2943) | S20: =LOOKUP(DATE($O20,S$25,S$24),$A$2:$A$2943,$C$2:$C$2943) | T20: =LOOKUP(DATE($O20,T$25,T$24),$A$2:$A$2943,$C$2:$C$2943) | U20: =LOOKUP(DATE($O20,U$25,U$24),$A$2:$A$2943,$C$2:$C$2943) | V20: =LOOKUP(DATE($O20,V$25,V$24),$A$2:$A$2943,$C$2:$C$2943) | W20: =LOOKUP(DATE($O20,W$25,W$24),$A$2:$A$2943,$C$2:$C$2943) | ... AA20: =LOOKUP(DATE($O20,AA$25,AA$24),$A$2:$A$2943,$C$2:$C$2943) | AD20: 2024 | AE20: =+P21 | AF20: =+Q21 | AG20: =+R21 | AH20: =+S21 | AI20: =+T21 | AJ20: =+U21 | AK20: =+V21 | AL20: =+W21 | ... AP20: =+AA21 | AQ20: =+(B233/B221-1)/COUNTA(AE20:AP20)*12 | AV20: Competencia | AW20: =LOOKUP(AW19,$F$2:$F$2974,$K$2:$K$2974) | AX20: =LOOKUP(AX19,$F$2:$F$2974,$K$2:$K$2974) | AY20: =LOOKUP(AY19,$F$2:$F$2974,$K$2:$K$2974) | AZ20: =LOOKUP(AZ19,$F$2:$F$2974,$K$2:$K$2974) | BA20: =LOOKUP(BA19,$F$2:$F$2974,$K$2:$K$2974) | BB20: =LOOKUP(BB19,$F$2:$F$2974,$K$2:$K$2974)
A21: 39262 | B21: 11812.23 | C21: =(B21/B20-1)/(A21-A20)*360 | D21: =B21/$B$3*100 | O21: 2024 | P21: =LOOKUP(DATE($O21,P$25,P$24),$A$2:$A$2943,$C$2:$C$2943) | Q21: =LOOKUP(DATE($O21,Q$25,Q$24),$A$2:$A$2943,$C$2:$C$2943) | R21: =LOOKUP(DATE($O21,R$25,R$24),$A$2:$A$2943,$C$2:$C$2943) | S21: =LOOKUP(DATE($O21,S$25,S$24),$A$2:$A$2943,$C$2:$C$2943) | T21: =LOOKUP(DATE($O21,T$25,T$24),$A$2:$A$2943,$C$2:$C$2943) | U21: =LOOKUP(DATE($O21,U$25,U$24),$A$2:$A$2943,$C$2:$C$2943) | V21: =LOOKUP(DATE($O21,V$25,V$24),$A$2:$A$2943,$C$2:$C$2943) | W21: =LOOKUP(DATE($O21,W$25,W$24),$A$2:$A$2943,$C$2:$C$2943) | ... AA21: =LOOKUP(DATE($O21,AA$25,AA$24),$A$2:$A$2943,$C$2:$C$2943) | AD21: 2025 | AE21: =+P22 | AF21: =+Q22 | AG21: =+R22 | AH21: =+S22 | AI21: =+T22 | AJ21: =+U22 | AK21: =+V22 | AL21: =+W22 | ... AP21: =+AA22 | AQ21: =+(B245/B234-1)/COUNTA(AE21:AP21)*12 | AV21: LIQUIDEZ RESERVA DÓLAR | AW21: =LOOKUP(AW19,$F$2:$F$2972,$H$2:$H$2972) | AX21: =LOOKUP(AX19,$F$2:$F$2972,$H$2:$H$2972) | AY21: =LOOKUP(AY19,$F$2:$F$2972,$H$2:$H$2972) | AZ21: =LOOKUP(AZ19,$F$2:$F$2972,$H$2:$H$2972) | BA21: =LOOKUP(BA19,$F$2:$F$2972,$H$2:$H$2972) | BB21: =LOOKUP(BB19,$F$2:$F$2972,$H$2:$H$2972)
A22: 39294 | B22: 11866.53 | C22: =(B22/B21-1)/(A22-A21)*360 | D22: =B22/$B$3*100 | O22: 2025 | P22: =LOOKUP(DATE($O22,P$25,P$24),$A$2:$A$2943,$C$2:$C$2943) | Q22: =LOOKUP(DATE($O22,Q$25,Q$24),$A$2:$A$2943,$C$2:$C$2943) | R22: =LOOKUP(DATE($O22,R$25,R$24),$A$2:$A$2943,$C$2:$C$2943) | S22: =LOOKUP(DATE($O22,S$25,S$24),$A$2:$A$2943,$C$2:$C$2943) | T22: =LOOKUP(DATE($O22,T$25,T$24),$A$2:$A$2943,$C$2:$C$2943) | U22: =LOOKUP(DATE($O22,U$25,U$24),$A$2:$A$2943,$C$2:$C$2943) | V22: =LOOKUP(DATE($O22,V$25,V$24),$A$2:$A$2943,$C$2:$C$2943) | W22: =LOOKUP(DATE($O22,W$25,W$24),$A$2:$A$2943,$C$2:$C$2943) | ... AA22: =LOOKUP(DATE($O22,AA$25,AA$24),$A$2:$A$2943,$C$2:$C$2943) | AD22: 2026 | AE22: =+P23 | AF22: =+Q23 | AG22: =+R23 | AH22: =+S23 | AQ22: =+(B249/B246-1)/COUNTA(AE22:AP22)*12
O23: 2026 | P23: =LOOKUP(DATE($O23,P$25,P$24),$A$2:$A$2943,$C$2:$C$2943) | Q23: =LOOKUP(DATE($O23,Q$25,Q$24),$A$2:$A$2943,$C$2:$C$2943) | R23: =LOOKUP(DATE($O23,R$25,R$24),$A$2:$A$2943,$C$2:$C$2943) | S23: =LOOKUP(DATE($O23,S$25,S$24),$A$2:$A$2943,$C$2:$C$2943)
A24: 39325 | B24: 11922.48 | C24: =(B24/B22-1)/(A24-A22)*360 | D24: =B24/$B$3*100 | P24: 31 | Q24: 28 | R24: 31 | S24: 30 | T24: 31 | U24: 30 | V24: 31 | W24: 31 | X24: 30 | Y24: 31 | Z24: 30 | AA24: 31 | AD24: (*) Acum a Mar
A25: 39353 | B25: 11975.61 | C25: =(B25/B24-1)/(A25-A24)*360 | D25: =B25/$B$3*100 | P25: 1 | Q25: 2 | R25: 3 | S25: 4 | T25: 5 | U25: 6 | V25: 7 | W25: 8 | X25: 9 | Y25: 10 | Z25: 11 | AA25: 12
A26: 39386 | B26: 12038.9 | C26: =(B26/B25-1)/(A26-A25)*360 | D26: =B26/$B$3*100 | O26: FONDO LIQUIDEZ RESERVA DÓLAR | P26: Ene | Q26: Feb | R26: Mar | S26: Abr | T26: May | U26: Jun | V26: Jul | W26: Ago | X26: Sep | Y26: Oct | Z26: Nov | AA26: Dic
A27: 39416 | B27: 12096.85 | C27: =(B27/B26-1)/(A27-A26)*360 | D27: =B27/$B$3*100 | O27: 2017 | T27: =LOOKUP(DATE($O27,T$25,T$24),$A$2:$A$2943,$I$2:$I$2943) | U27: =LOOKUP(DATE($O27,U$25,U$24),$A$2:$A$2943,$I$2:$I$2943) | V27: =LOOKUP(DATE($O27,V$25,V$24),$A$2:$A$2943,$I$2:$I$2943) | W27: =LOOKUP(DATE($O27,W$25,W$24),$A$2:$A$2943,$I$2:$I$2943) | X27: =LOOKUP(DATE($O27,X$25,X$24),$A$2:$A$2943,$I$2:$I$2943) | Y27: =LOOKUP(DATE($O27,Y$25,Y$24),$A$2:$A$2943,$I$2:$I$2943) | Z27: =LOOKUP(DATE($O27,Z$25,Z$24),$A$2:$A$2943,$I$2:$I$2943) | AA27: =LOOKUP(DATE($O27,AA$25,AA$24),$A$2:$A$2943,$I$2:$I$2943) | AD27: LIQUIDEZ RESERVA DÓLAR | AE27: Ene | AF27: Feb | AG27: Mar | AH27: Abr | AI27: May | AJ27: Jun | AK27: Jul | AL27: Ago | AM27: Sep | AN27: Oct | AO27: Nov | AP27: Dic | AQ27: Total Año | AW27: Rentabilidad | AX27: Mensual | AY27: Trimestral | AZ27: Semestral | BA27: Anual | BB27: Acum. 2026
A28: 39447 | B28: 12152.6 | C28: =(B28/B27-1)/(A28-A27)*360 | D28: =B28/$B$3*100 | O28: 2018 | P28: =LOOKUP(DATE($O28,P$25,P$24),$A$2:$A$2943,$I$2:$I$2943) | Q28: =LOOKUP(DATE($O28,Q$25,Q$24),$A$2:$A$2943,$I$2:$I$2943) | R28: =LOOKUP(DATE($O28,R$25,R$24),$A$2:$A$2943,$I$2:$I$2943) | S28: =LOOKUP(DATE($O28,S$25,S$24),$A$2:$A$2943,$I$2:$I$2943) | T28: =LOOKUP(DATE($O28,T$25,T$24),$A$2:$A$2943,$I$2:$I$2943) | U28: =LOOKUP(DATE($O28,U$25,U$24),$A$2:$A$2943,$I$2:$I$2943) | V28: =LOOKUP(DATE($O28,V$25,V$24),$A$2:$A$2943,$I$2:$I$2943) | W28: =LOOKUP(DATE($O28,W$25,W$24),$A$2:$A$2943,$I$2:$I$2943) | ... AA28: =LOOKUP(DATE($O28,AA$25,AA$24),$A$2:$A$2943,$I$2:$I$2943) | AD28: 2017 | AR28: (*) | AW28: Competencia | AX28: =($AW20/AX20-1)/(AW19-AX19)*360 | AY28: =($AW20/AY20-1)/($AW$19-AY19)*360 | AZ28: =($AW20/AZ20-1)/($AW$19-AZ19)*360 | BA28: =($AW20/BA20-1)/($AW$19-BA19)*360 | BB28: =AQ80
A29: 39478 | B29: 12223.14 | C29: =(B29/B28-1)/(A29-A28)*360 | D29: =B29/$B$3*100 | O29: 2019 | P29: =LOOKUP(DATE($O29,P$25,P$24),$A$2:$A$2943,$I$2:$I$2943) | Q29: =LOOKUP(DATE($O29,Q$25,Q$24),$A$2:$A$2943,$I$2:$I$2943) | R29: =LOOKUP(DATE($O29,R$25,R$24),$A$2:$A$2943,$I$2:$I$2943) | S29: =LOOKUP(DATE($O29,S$25,S$24),$A$2:$A$2943,$I$2:$I$2943) | T29: =LOOKUP(DATE($O29,T$25,T$24),$A$2:$A$2943,$I$2:$I$2943) | U29: =LOOKUP(DATE($O29,U$25,U$24),$A$2:$A$2943,$I$2:$I$2943) | V29: =LOOKUP(DATE($O29,V$25,V$24),$A$2:$A$2943,$I$2:$I$2943) | W29: =LOOKUP(DATE($O29,W$25,W$24),$A$2:$A$2943,$I$2:$I$2943) | ... AA29: =LOOKUP(DATE($O29,AA$25,AA$24),$A$2:$A$2943,$I$2:$I$2943) | AD29: 2018 | AW29: LIQUIDEZ RESERVA DÓLAR | AX29: =($AW21/AX21-1)/($AW$19-AX19)*360 | AY29: =($AW21/AY21-1)/($AW$19-AY19)*360 | AZ29: =($AW21/AZ21-1)/($AW$19-AZ19)*360 | BA29: =($AW21/BA21-1)/($AW$19-BA19)*360 | BB29: =+AQ81
A30: 39507 | B30: 12284.88 | C30: =(B30/B29-1)/(A30-A29)*360 | D30: =B30/$B$3*100 | O30: 2020 | P30: =LOOKUP(DATE($O30,P$25,P$24),$A$2:$A$2943,$I$2:$I$2943) | Q30: =LOOKUP(DATE($O30,Q$25,Q$24)+1,$A$2:$A$2943,$I$2:$I$2943) | R30: =LOOKUP(DATE($O30,R$25,R$24),$A:$A,$I:$I) | S30: =LOOKUP(DATE($O30,S$25,S$24),$A:$A,$I:$I) | T30: =LOOKUP(DATE($O30,T$25,T$24),$A:$A,$I:$I) | U30: =LOOKUP(DATE($O30,U$25,U$24),$A:$A,$I:$I) | V30: =LOOKUP(DATE($O30,V$25,V$24),$A:$A,$I:$I) | W30: =LOOKUP(DATE($O30,W$25,W$24),$A:$A,$I:$I) | X30: =LOOKUP(DATE($O30,X$25,X$24),$A:$A,$I:$I) | Y30: =+I183 | Z30: =+I184 | AA30: =+I185 | AD30: 2019
A31: 39538 | B31: 12351.45 | C31: =(B31/B30-1)/(A31-A30)*360 | D31: =B31/$B$3*100 | O31: 2021 | P31: =+I186 | Q31: =+I187 | R31: =+I188 | S31: =+I189 | T31: =+I190 | U31: =+I191 | V31: =+I192 | W31: =+I193 | X31: =+I194 | Y31: =+I195 | Z31: =+I196 | AA31: =+I197 | AD31: 2020
A32: 39568 | B32: 12416.18 | C32: =(B32/B31-1)/(A32-A31)*360 | D32: =B32/$B$3*100 | O32: 2022 | P32: =+I198 | Q32: =+I199 | R32: =+I200 | S32: =+I201 | T32: =+I202 | U32: =+I203 | V32: =+I204 | W32: =+I205 | X32: =+I206 | Y32: =+I207 | Z32: =+I208 | AA32: =+I209 | AD32: 2021 | AJ32: =+U31 | AK32: =+V31 | AL32: =+W31 | AM32: =+X31 | AN32: =+Y31 | AO32: =+Z31 | AP32: =+AA31 | AQ32: =+(H197/H190-1)/COUNTA(AE32:AP32)*12
A33: 39598 | B33: 12481.48 | C33: =(B33/B32-1)/(A33-A32)*360 | D33: =B33/$B$3*100 | O33: 2023 | P33: =+I210 | Q33: =+I211 | R33: =+I212 | S33: =+I213 | T33: =+I214 | U33: =+I215 | V33: =+I216 | W33: =+I217 | X33: =+I218 | Y33: =+I219 | Z33: =+I220 | AA33: =+I221 | AD33: 2022 | AE33: =+P32 | AF33: =+Q32 | AG33: =+R32 | AH33: =+S32 | AI33: =+T32 | AJ33: =+U32 | AK33: =+V32 | AL33: =+W32 | ... AP33: =+AA32 | AQ33: =+(H209/H197-1)/COUNTA(AE33:AP33)*12
A34: 39629 | B34: 12552.23 | C34: =(B34/B33-1)/(A34-A33)*360 | D34: =B34/$B$3*100 | O34: 2024 | P34: =+I222 | Q34: =+I223 | R34: =+I224 | S34: =+I225 | T34: =+I226 | U34: =+I227 | V34: =+I228 | W34: =+I229 | X34: =+I230 | Y34: =+I231 | Z34: =+I232 | AA34: =+I233 | AD34: 2023 | AE34: =+P33 | AF34: =+Q33 | AG34: =+R33 | AH34: =+S33 | AI34: =+T33 | AJ34: =+U33 | AK34: =+V33 | AL34: =+W33 | ... AP34: =+AA33 | AQ34: =+(H221/H209-1)/COUNTA(AE34:AP34)*12
A35: 39660 | B35: 12628.9 | C35: =(B35/B34-1)/(A35-A34)*360 | D35: =B35/$B$3*100 | O35: 2025 | P35: =+I234 | Q35: 0 | R35: =+I236 | S35: =+I237 | T35: =+I238 | U35: =+I239 | V35: =+I240 | W35: =+I241 | X35: =+I242 | Y35: =+I243 | Z35: =+I244 | AA35: =+I245 | AD35: 2024 | AE35: =+P34 | AF35: =+Q34 | AG35: =+R34 | AH35: =+S34 | AI35: =+T34 | AJ35: =+U34 | AK35: =+V34 | AL35: =+W34 | ... AP35: =+AA34 | AQ35: =+(H233/H221-1)/COUNTA(AE35:AP35)*12
O36: 2026 | P36: =+I246 | Q36: =+I247 | R36: =+I248 | S36: =+I249 | T36: =+I250 | U36: =+I251 | AD36: 2025 | AE36: =+P35 | AF36: =+Q35 | AG36: =+R35 | AH36: =+S35 | AI36: =+T35 | AJ36: =+U35 | AK36: =+V35 | AL36: =+W35 | ... AP36: =+AA35 | AQ36: =+(H245/H234-1)/COUNTA(AE36:AP36)*12
A37: 39689 | B37: 12704.63 | C37: =(B37/B35-1)/(A37-A35)*360 | D37: =B37/$B$3*100 | P37: 31 | Q37: 28 | R37: 31 | S37: 30 | T37: 31 | U37: 30 | V37: 31 | W37: 31 | X37: 30 | Y37: 31 | Z37: 30 | AA37: 31 | AD37: 2026 | AE37: =+P36 | AF37: =+Q36 | AG37: =+R36 | AH37: =+S36 | AI37: =+T36/S36-1 | AJ37: =+U36/T36-1 | AQ37: =+(H249/H246-1)/COUNTA(AE37:AJ37)*12
A38: 39721 | B38: 12796.95 | C38: =(B38/B37-1)/(A38-A37)*360 | D38: =B38/$B$3*100 | P38: 1 | Q38: 2 | R38: 3 | S38: 4 | T38: 4 | U38: 6 | V38: 7 | W38: 8 | X38: 9 | Y38: 10 | Z38: 11 | AA38: 12 | AD38: (*) Acum a Mar | AR38: (*)
A39: 39752 | B39: 12885.37 | C39: =(B39/B38-1)/(A39-A38)*360 | D39: =B39/$B$3*100 | O39: Competencia | P39: Ene | Q39: Feb | R39: Mar | S39: Abr | T39: May | U39: Jun | V39: Jul | W39: Ago | X39: Sep | Y39: Oct | Z39: Nov | AA39: Dic | AD39: Competencia | AE39: Ene | AF39: Feb | AG39: Mar | AH39: Abr | AI39: May | AJ39: Jun | AK39: Jul | AL39: Ago | AM39: Sep | AN39: Oct | AO39: Nov | AP39: Dic | AQ39: Total Año
A40: 39780 | B40: 12970.93 | C40: =(B40/B39-1)/(A40-A39)*360 | D40: =B40/$B$3*100 | O40: 2017 | T40: =LOOKUP(DATE($O40,T$25,T$24),$A$2:$A$2943,$L$2:$L$2943) | U40: =LOOKUP(DATE($O40,U$25,U$24),$A$2:$A$2943,$L$2:$L$2943) | V40: =LOOKUP(DATE($O40,V$25,V$24),$A$2:$A$2943,$L$2:$L$2943) | W40: =LOOKUP(DATE($O40,W$25,W$24),$A$2:$A$2943,$L$2:$L$2943) | X40: =LOOKUP(DATE($O40,X$25,X$24),$A$2:$A$2943,$L$2:$L$2943) | Y40: =LOOKUP(DATE($O40,Y$25,Y$24),$A$2:$A$2943,$L$2:$L$2943) | Z40: =LOOKUP(DATE($O40,Z$25,Z$24),$A$2:$A$2943,$L$2:$L$2943) | AA40: =LOOKUP(DATE($O40,AA$25,AA$24),$A$2:$A$2943,$L$2:$L$2943) | AD40: 2017 | AI40: =+T40 | AJ40: =+U40 | AK40: =+V40 | AL40: =+W40 | AM40: =+X40 | AN40: =+Y40 | AO40: =+Z40 | AP40: =+AA40 | AQ40: =+(K149/K141-1)/8*12
...

Sheet rentabilidad
S1: Rentabilidad | T1: Mensual | U1: Trimestral | V1: Semestral | W1: Anual | X1: Acum 2026 (*)
S2: Competencia | T2: =+'Datos ICP (2)'!AX28 | U2: =+'Datos ICP (2)'!AY28 | V2: =+'Datos ICP (2)'!AZ28 | W2: =+'Datos ICP (2)'!BA28 | X2: =+'Datos ICP (2)'!BB28
S3: LIQUIDEZ RESERVA DÓLAR | T3: =+'Datos ICP (2)'!AX29 | U3: =+'Datos ICP (2)'!AY29 | V3: =+'Datos ICP (2)'!AZ29 | W3: =+'Datos ICP (2)'!BA29 | X3: =+'Datos ICP (2)'!BB29
C6: Año | D6: Fondo | E6: Ene | F6: Feb | G6: Mar | H6: Abr | I6: May | J6: Jun | K6: Jul | L6: Ago | M6: Sep | N6: Oct | O6: Nov | P6: Dic | Q6: Total Año
C8: 2017 | D8: Competencia
D9: LIQUIDEZ DÓLAR
C10: 2018 | D10: Competencia
D11: LIQUIDEZ DÓLAR
C12: 2019 | D12: Competencia
D13: LIQUIDEZ DÓLAR
C14: 2020 | D14: Competencia
D15: LIQUIDEZ DÓLAR
C16: 2021 | D16: Competencia
D17: LIQUIDEZ RESERVA DÓLAR
C18: 2022 | D18: Competencia
D19: LIQUIDEZ DÓLAR
C20: 2023 | D20: Competencia
D21: LIQUIDEZ RESERVA DÓLAR
C22: 2024 | D22: Competencia
D23: LIQUIDEZ RESERVA DÓLAR | Q23: 0
C24: 2025 | D24: Competencia | G24: =+'Datos ICP (2)'!AG78 | H24: =+'Datos ICP (2)'!AH78 | I24: =+'Datos ICP (2)'!AI78 | J24: =+'Datos ICP (2)'!AJ78 | K24: =+'Datos ICP (2)'!AK78 | L24: =+'Datos ICP (2)'!AL78 | M24: =+'Datos ICP (2)'!AM78 | N24: =+'Datos ICP (2)'!AN78 | ... Q24: =+'Datos ICP (2)'!AQ78
D25: LIQUIDEZ RESERVA DÓLAR | G25: =+'Datos ICP (2)'!AG79 | H25: =+'Datos ICP (2)'!AH79 | I25: =+'Datos ICP (2)'!AI79 | J25: =+'Datos ICP (2)'!AJ79 | K25: =+'Datos ICP (2)'!AK79 | L25: =+'Datos ICP (2)'!AL79 | M25: =+'Datos ICP (2)'!AM79 | N25: =+'Datos ICP (2)'!AN79 | ... Q25: =+'Datos ICP (2)'!AQ79
C26: 2026 | D26: Competencia | E26: =+'Datos ICP (2)'!AE80 | F26: =+'Datos ICP (2)'!AF80 | G26: =+'Datos ICP (2)'!AG80 | H26: =+'Datos ICP (2)'!AH80 | Q26: =+'Datos ICP (2)'!AQ80
D27: LIQUIDEZ RESERVA DÓLAR | E27: =+'Datos ICP (2)'!AE81 | F27: =+'Datos ICP (2)'!AF81 | G27: =+'Datos ICP (2)'!AG81 | H27: =+'Datos ICP (2)'!AH81 | Q27: =+'Datos ICP (2)'!AQ81

Sheet composición
J1: Duración | N1: Instrumentos | R1: Moneda
O2: Bono | P2: 0
K3: Menos de 1 mes | L3: 0.1757 | O3: Depósitos | P3: 0 | S3: USD | T3: 1
K4: 1-3 meses | L4: 0.6108 | O4: Factoring | P4: 0
K5: 3-4 meses | L5: 0.2135 | O5: Financiamiento Inmobiliario | P5: 0
K6: Más de 4 meses | L6: 0 | O6: Financiamiento Mesa Moneda Extranjera | P6: 0.8108
L7: =SUM(L3:L6) | O7: Garantías | P7: 0
O8: Nota Estructurada | P8: 0.1892
O9: Financiamiento Mesa Renta Fija | P9: 0
O10: Simultánea | P10: 0
O11: Efectos de Comercio | P11: 0
O13: Pagaré | P13: 0
A14: Facturas | B14: 0
P15: =SUM(P2:P13)
